{
  "name": "Rollercoaster Race",
  "version": 1,
  "author": "Minecraft Rollercoaster Generator",
  "description": "A stunning 4-5 player competitive rollercoaster race",
  "tracks": 5,
  "blocks": [
    {
      "x": 0,
      "y": 64,
      "z": 0,
      "type": "powered_rail",
      "metadata": 0,
      "track_id": 0
    },
    {
      "x": 0,
      "y": 65,
      "z": 0,
      "type": "powered_rail",
      "metadata": 0,
      "track_id": 0
    },
    {
      "x": 0,
      "y": 66,
      "z": 0,
      "type": "powered_rail",
      "metadata": 0,
      "track_id": 0
    },
    {
      "x": 0,
      "y": 67,
      "z": 0,
      "type": "powered_rail",
      "metadata": 0,
      "track_id": 0
    },
    {
      "x": 0,
      "y": 68,
      "z": 0,
      "type": "powered_rail",
      "metadata": 0,
      "track_id": 0
    },
    {
      "x": 0,
      "y": 69,
      "z": 0,
      "type": "powered_rail",
      "metadata": 0,
      "track_id": 0
    },
    {
      "x": 0,
      "y": 70,
      "z": 0,
      "type": "powered_rail",
      "metadata": 0,
      "track_id": 0
    },
    {
      "x": 0,
      "y": 71,
      "z": 0,
      "type": "powered_rail",
      "metadata": 0,
      "track_id": 0
    },
    {
      "x": 0,
      "y": 72,
      "z": 0,
      "type": "powered_rail",
      "metadata": 0,
      "track_id": 0
    },
    {
      "x": 0,
      "y": 73,
      "z": 0,
      "type": "powered_rail",
      "metadata": 0,
      "track_id": 0
    },
    {
      "x": 5,
      "y": 64,
      "z": 0,
      "type": "powered_rail",
      "metadata": 0,
      "track_id": 0
    },
    {
      "x": 4,
      "y": 65,
      "z": 0,
      "type": "powered_rail",
      "metadata": 0,
      "track_id": 0
    },
    {
      "x": 4,
      "y": 66,
      "z": 0,
      "type": "powered_rail",
      "metadata": 0,
      "track_id": 0
    },
    {
      "x": 4,
      "y": 67,
      "z": 0,
      "type": "powered_rail",
      "metadata": 0,
      "track_id": 0
    },
    {
      "x": 3,
      "y": 69,
      "z": 0,
      "type": "powered_rail",
      "metadata": 0,
      "track_id": 0
    },
    {
      "x": 3,
      "y": 70,
      "z": 0,
      "type": "powered_rail",
      "metadata": 0,
      "track_id": 0
    },
    {
      "x": 2,
      "y": 70,
      "z": 0,
      "type": "powered_rail",
      "metadata": 0,
      "track_id": 0
    },
    {
      "x": 1,
      "y": 71,
      "z": 0,
      "type": "powered_rail",
      "metadata": 0,
      "track_id": 0
    },
    {
      "x": 0,
      "y": 71,
      "z": 0,
      "type": "powered_rail",
      "metadata": 0,
      "track_id": 0
    },
    {
      "x": 0,
      "y": 72,
      "z": 0,
      "type": "powered_rail",
      "metadata": 0,
      "track_id": 0
    },
    {
      "x": 0,
      "y": 71,
      "z": 0,
      "type": "powered_rail",
      "metadata": 0,
      "track_id": 0
    },
    {
      "x": -1,
      "y": 71,
      "z": 0,
      "type": "powered_rail",
      "metadata": 0,
      "track_id": 0
    },
    {
      "x": -2,
      "y": 70,
      "z": 0,
      "type": "powered_rail",
      "metadata": 0,
      "track_id": 0
    },
    {
      "x": -3,
      "y": 70,
      "z": 0,
      "type": "powered_rail",
      "metadata": 0,
      "track_id": 0
    },
    {
      "x": -3,
      "y": 69,
      "z": 0,
      "type": "powered_rail",
      "metadata": 0,
      "track_id": 0
    },
    {
      "x": -4,
      "y": 67,
      "z": 0,
      "type": "powered_rail",
      "metadata": 0,
      "track_id": 0
    },
    {
      "x": -4,
      "y": 66,
      "z": 0,
      "type": "powered_rail",
      "metadata": 0,
      "track_id": 0
    },
    {
      "x": -4,
      "y": 65,
      "z": 0,
      "type": "powered_rail",
      "metadata": 0,
      "track_id": 0
    },
    {
      "x": -5,
      "y": 64,
      "z": 0,
      "type": "powered_rail",
      "metadata": 0,
      "track_id": 0
    },
    {
      "x": -4,
      "y": 63,
      "z": 0,
      "type": "powered_rail",
      "metadata": 0,
      "track_id": 0
    },
    {
      "x": -4,
      "y": 62,
      "z": 0,
      "type": "powered_rail",
      "metadata": 0,
      "track_id": 0
    },
    {
      "x": -4,
      "y": 60,
      "z": 0,
      "type": "powered_rail",
      "metadata": 0,
      "track_id": 0
    },
    {
      "x": -3,
      "y": 59,
      "z": 0,
      "type": "powered_rail",
      "metadata": 0,
      "track_id": 0
    },
    {
      "x": -3,
      "y": 58,
      "z": 0,
      "type": "powered_rail",
      "metadata": 0,
      "track_id": 0
    },
    {
      "x": -2,
      "y": 58,
      "z": 0,
      "type": "powered_rail",
      "metadata": 0,
      "track_id": 0
    },
    {
      "x": -1,
      "y": 57,
      "z": 0,
      "type": "powered_rail",
      "metadata": 0,
      "track_id": 0
    },
    {
      "x": 0,
      "y": 57,
      "z": 0,
      "type": "powered_rail",
      "metadata": 0,
      "track_id": 0
    },
    {
      "x": 0,
      "y": 56,
      "z": 0,
      "type": "powered_rail",
      "metadata": 0,
      "track_id": 0
    },
    {
      "x": 0,
      "y": 57,
      "z": 0,
      "type": "powered_rail",
      "metadata": 0,
      "track_id": 0
    },
    {
      "x": 1,
      "y": 57,
      "z": 0,
      "type": "powered_rail",
      "metadata": 0,
      "track_id": 0
    },
    {
      "x": 2,
      "y": 58,
      "z": 0,
      "type": "powered_rail",
      "metadata": 0,
      "track_id": 0
    },
    {
      "x": 3,
      "y": 58,
      "z": 0,
      "type": "powered_rail",
      "metadata": 0,
      "track_id": 0
    },
    {
      "x": 3,
      "y": 59,
      "z": 0,
      "type": "powered_rail",
      "metadata": 0,
      "track_id": 0
    },
    {
      "x": 4,
      "y": 60,
      "z": 0,
      "type": "powered_rail",
      "metadata": 0,
      "track_id": 0
    },
    {
      "x": 4,
      "y": 62,
      "z": 0,
      "type": "powered_rail",
      "metadata": 0,
      "track_id": 0
    },
    {
      "x": 4,
      "y": 63,
      "z": 0,
      "type": "powered_rail",
      "metadata": 0,
      "track_id": 0
    },
    {
      "x": 0,
      "y": 64,
      "z": 0,
      "type": "powered_rail",
      "metadata": 0,
      "track_id": 0
    },
    {
      "x": 0,
      "y": 63,
      "z": 0,
      "type": "powered_rail",
      "metadata": 0,
      "track_id": 0
    },
    {
      "x": 0,
      "y": 62,
      "z": 0,
      "type": "powered_rail",
      "metadata": 0,
      "track_id": 0
    },
    {
      "x": 0,
      "y": 61,
      "z": 0,
      "type": "powered_rail",
      "metadata": 0,
      "track_id": 0
    },
    {
      "x": 0,
      "y": 60,
      "z": 0,
      "type": "powered_rail",
      "metadata": 0,
      "track_id": 0
    },
    {
      "x": 0,
      "y": 59,
      "z": 0,
      "type": "powered_rail",
      "metadata": 0,
      "track_id": 0
    },
    {
      "x": 0,
      "y": 58,
      "z": 0,
      "type": "powered_rail",
      "metadata": 0,
      "track_id": 0
    },
    {
      "x": 0,
      "y": 57,
      "z": 0,
      "type": "powered_rail",
      "metadata": 0,
      "track_id": 0
    },
    {
      "x": 0,
      "y": 56,
      "z": 0,
      "type": "powered_rail",
      "metadata": 0,
      "track_id": 0
    },
    {
      "x": 0,
      "y": 55,
      "z": 0,
      "type": "powered_rail",
      "metadata": 0,
      "track_id": 0
    },
    {
      "x": 0,
      "y": 54,
      "z": 0,
      "type": "powered_rail",
      "metadata": 0,
      "track_id": 0
    },
    {
      "x": 0,
      "y": 53,
      "z": 0,
      "type": "powered_rail",
      "metadata": 0,
      "track_id": 0
    },
    {
      "x": 0,
      "y": 52,
      "z": 0,
      "type": "powered_rail",
      "metadata": 0,
      "track_id": 0
    },
    {
      "x": 0,
      "y": 51,
      "z": 0,
      "type": "powered_rail",
      "metadata": 0,
      "track_id": 0
    },
    {
      "x": 0,
      "y": 50,
      "z": 0,
      "type": "powered_rail",
      "metadata": 0,
      "track_id": 0
    },
    {
      "x": 0,
      "y": 64,
      "z": 0,
      "type": "powered_rail",
      "metadata": 0,
      "track_id": 0
    },
    {
      "x": 1,
      "y": 64,
      "z": 0,
      "type": "powered_rail",
      "metadata": 0,
      "track_id": 0
    },
    {
      "x": 2,
      "y": 64,
      "z": 0,
      "type": "powered_rail",
      "metadata": 0,
      "track_id": 0
    },
    {
      "x": 3,
      "y": 64,
      "z": 0,
      "type": "powered_rail",
      "metadata": 0,
      "track_id": 0
    },
    {
      "x": 4,
      "y": 64,
      "z": 0,
      "type": "powered_rail",
      "metadata": 0,
      "track_id": 0
    },
    {
      "x": 20,
      "y": 64,
      "z": 0,
      "type": "powered_rail",
      "metadata": 0,
      "track_id": 1
    },
    {
      "x": 20,
      "y": 65,
      "z": 0,
      "type": "powered_rail",
      "metadata": 0,
      "track_id": 1
    },
    {
      "x": 20,
      "y": 66,
      "z": 0,
      "type": "powered_rail",
      "metadata": 0,
      "track_id": 1
    },
    {
      "x": 20,
      "y": 67,
      "z": 0,
      "type": "powered_rail",
      "metadata": 0,
      "track_id": 1
    },
    {
      "x": 20,
      "y": 68,
      "z": 0,
      "type": "powered_rail",
      "metadata": 0,
      "track_id": 1
    },
    {
      "x": 20,
      "y": 69,
      "z": 0,
      "type": "powered_rail",
      "metadata": 0,
      "track_id": 1
    },
    {
      "x": 20,
      "y": 70,
      "z": 0,
      "type": "powered_rail",
      "metadata": 0,
      "track_id": 1
    },
    {
      "x": 20,
      "y": 71,
      "z": 0,
      "type": "powered_rail",
      "metadata": 0,
      "track_id": 1
    },
    {
      "x": 20,
      "y": 72,
      "z": 0,
      "type": "powered_rail",
      "metadata": 0,
      "track_id": 1
    },
    {
      "x": 20,
      "y": 73,
      "z": 0,
      "type": "powered_rail",
      "metadata": 0,
      "track_id": 1
    },
    {
      "x": 25,
      "y": 64,
      "z": 0,
      "type": "powered_rail",
      "metadata": 0,
      "track_id": 1
    },
    {
      "x": 24,
      "y": 65,
      "z": 0,
      "type": "powered_rail",
      "metadata": 0,
      "track_id": 1
    },
    {
      "x": 24,
      "y": 66,
      "z": 0,
      "type": "powered_rail",
      "metadata": 0,
      "track_id": 1
    },
    {
      "x": 24,
      "y": 67,
      "z": 0,
      "type": "powered_rail",
      "metadata": 0,
      "track_id": 1
    },
    {
      "x": 23,
      "y": 69,
      "z": 0,
      "type": "powered_rail",
      "metadata": 0,
      "track_id": 1
    },
    {
      "x": 23,
      "y": 70,
      "z": 0,
      "type": "powered_rail",
      "metadata": 0,
      "track_id": 1
    },
    {
      "x": 22,
      "y": 70,
      "z": 0,
      "type": "powered_rail",
      "metadata": 0,
      "track_id": 1
    },
    {
      "x": 21,
      "y": 71,
      "z": 0,
      "type": "powered_rail",
      "metadata": 0,
      "track_id": 1
    },
    {
      "x": 20,
      "y": 71,
      "z": 0,
      "type": "powered_rail",
      "metadata": 0,
      "track_id": 1
    },
    {
      "x": 20,
      "y": 72,
      "z": 0,
      "type": "powered_rail",
      "metadata": 0,
      "track_id": 1
    },
    {
      "x": 20,
      "y": 71,
      "z": 0,
      "type": "powered_rail",
      "metadata": 0,
      "track_id": 1
    },
    {
      "x": 19,
      "y": 71,
      "z": 0,
      "type": "powered_rail",
      "metadata": 0,
      "track_id": 1
    },
    {
      "x": 18,
      "y": 70,
      "z": 0,
      "type": "powered_rail",
      "metadata": 0,
      "track_id": 1
    },
    {
      "x": 17,
      "y": 70,
      "z": 0,
      "type": "powered_rail",
      "metadata": 0,
      "track_id": 1
    },
    {
      "x": 17,
      "y": 69,
      "z": 0,
      "type": "powered_rail",
      "metadata": 0,
      "track_id": 1
    },
    {
      "x": 16,
      "y": 67,
      "z": 0,
      "type": "powered_rail",
      "metadata": 0,
      "track_id": 1
    },
    {
      "x": 16,
      "y": 66,
      "z": 0,
      "type": "powered_rail",
      "metadata": 0,
      "track_id": 1
    },
    {
      "x": 16,
      "y": 65,
      "z": 0,
      "type": "powered_rail",
      "metadata": 0,
      "track_id": 1
    },
    {
      "x": 15,
      "y": 64,
      "z": 0,
      "type": "powered_rail",
      "metadata": 0,
      "track_id": 1
    },
    {
      "x": 16,
      "y": 63,
      "z": 0,
      "type": "powered_rail",
      "metadata": 0,
      "track_id": 1
    },
    {
      "x": 16,
      "y": 62,
      "z": 0,
      "type": "powered_rail",
      "metadata": 0,
      "track_id": 1
    },
    {
      "x": 16,
      "y": 60,
      "z": 0,
      "type": "powered_rail",
      "metadata": 0,
      "track_id": 1
    },
    {
      "x": 17,
      "y": 59,
      "z": 0,
      "type": "powered_rail",
      "metadata": 0,
      "track_id": 1
    },
    {
      "x": 17,
      "y": 58,
      "z": 0,
      "type": "powered_rail",
      "metadata": 0,
      "track_id": 1
    },
    {
      "x": 18,
      "y": 58,
      "z": 0,
      "type": "powered_rail",
      "metadata": 0,
      "track_id": 1
    },
    {
      "x": 19,
      "y": 57,
      "z": 0,
      "type": "powered_rail",
      "metadata": 0,
      "track_id": 1
    },
    {
      "x": 20,
      "y": 57,
      "z": 0,
      "type": "powered_rail",
      "metadata": 0,
      "track_id": 1
    },
    {
      "x": 20,
      "y": 56,
      "z": 0,
      "type": "powered_rail",
      "metadata": 0,
      "track_id": 1
    },
    {
      "x": 20,
      "y": 57,
      "z": 0,
      "type": "powered_rail",
      "metadata": 0,
      "track_id": 1
    },
    {
      "x": 21,
      "y": 57,
      "z": 0,
      "type": "powered_rail",
      "metadata": 0,
      "track_id": 1
    },
    {
      "x": 22,
      "y": 58,
      "z": 0,
      "type": "powered_rail",
      "metadata": 0,
      "track_id": 1
    },
    {
      "x": 23,
      "y": 58,
      "z": 0,
      "type": "powered_rail",
      "metadata": 0,
      "track_id": 1
    },
    {
      "x": 23,
      "y": 59,
      "z": 0,
      "type": "powered_rail",
      "metadata": 0,
      "track_id": 1
    },
    {
      "x": 24,
      "y": 60,
      "z": 0,
      "type": "powered_rail",
      "metadata": 0,
      "track_id": 1
    },
    {
      "x": 24,
      "y": 62,
      "z": 0,
      "type": "powered_rail",
      "metadata": 0,
      "track_id": 1
    },
    {
      "x": 24,
      "y": 63,
      "z": 0,
      "type": "powered_rail",
      "metadata": 0,
      "track_id": 1
    },
    {
      "x": 20,
      "y": 64,
      "z": 0,
      "type": "powered_rail",
      "metadata": 0,
      "track_id": 1
    },
    {
      "x": 20,
      "y": 63,
      "z": 0,
      "type": "powered_rail",
      "metadata": 0,
      "track_id": 1
    },
    {
      "x": 20,
      "y": 62,
      "z": 0,
      "type": "powered_rail",
      "metadata": 0,
      "track_id": 1
    },
    {
      "x": 20,
      "y": 61,
      "z": 0,
      "type": "powered_rail",
      "metadata": 0,
      "track_id": 1
    },
    {
      "x": 20,
      "y": 60,
      "z": 0,
      "type": "powered_rail",
      "metadata": 0,
      "track_id": 1
    },
    {
      "x": 20,
      "y": 59,
      "z": 0,
      "type": "powered_rail",
      "metadata": 0,
      "track_id": 1
    },
    {
      "x": 20,
      "y": 58,
      "z": 0,
      "type": "powered_rail",
      "metadata": 0,
      "track_id": 1
    },
    {
      "x": 20,
      "y": 57,
      "z": 0,
      "type": "powered_rail",
      "metadata": 0,
      "track_id": 1
    },
    {
      "x": 20,
      "y": 56,
      "z": 0,
      "type": "powered_rail",
      "metadata": 0,
      "track_id": 1
    },
    {
      "x": 20,
      "y": 55,
      "z": 0,
      "type": "powered_rail",
      "metadata": 0,
      "track_id": 1
    },
    {
      "x": 20,
      "y": 54,
      "z": 0,
      "type": "powered_rail",
      "metadata": 0,
      "track_id": 1
    },
    {
      "x": 20,
      "y": 53,
      "z": 0,
      "type": "powered_rail",
      "metadata": 0,
      "track_id": 1
    },
    {
      "x": 20,
      "y": 52,
      "z": 0,
      "type": "powered_rail",
      "metadata": 0,
      "track_id": 1
    },
    {
      "x": 20,
      "y": 51,
      "z": 0,
      "type": "powered_rail",
      "metadata": 0,
      "track_id": 1
    },
    {
      "x": 20,
      "y": 50,
      "z": 0,
      "type": "powered_rail",
      "metadata": 0,
      "track_id": 1
    },
    {
      "x": 20,
      "y": 64,
      "z": 0,
      "type": "powered_rail",
      "metadata": 0,
      "track_id": 1
    },
    {
      "x": 21,
      "y": 64,
      "z": 0,
      "type": "powered_rail",
      "metadata": 0,
      "track_id": 1
    },
    {
      "x": 22,
      "y": 64,
      "z": 0,
      "type": "powered_rail",
      "metadata": 0,
      "track_id": 1
    },
    {
      "x": 23,
      "y": 64,
      "z": 0,
      "type": "powered_rail",
      "metadata": 0,
      "track_id": 1
    },
    {
      "x": 24,
      "y": 64,
      "z": 0,
      "type": "powered_rail",
      "metadata": 0,
      "track_id": 1
    },
    {
      "x": 40,
      "y": 64,
      "z": 0,
      "type": "powered_rail",
      "metadata": 0,
      "track_id": 2
    },
    {
      "x": 40,
      "y": 65,
      "z": 0,
      "type": "powered_rail",
      "metadata": 0,
      "track_id": 2
    },
    {
      "x": 40,
      "y": 66,
      "z": 0,
      "type": "powered_rail",
      "metadata": 0,
      "track_id": 2
    },
    {
      "x": 40,
      "y": 67,
      "z": 0,
      "type": "powered_rail",
      "metadata": 0,
      "track_id": 2
    },
    {
      "x": 40,
      "y": 68,
      "z": 0,
      "type": "powered_rail",
      "metadata": 0,
      "track_id": 2
    },
    {
      "x": 40,
      "y": 69,
      "z": 0,
      "type": "powered_rail",
      "metadata": 0,
      "track_id": 2
    },
    {
      "x": 40,
      "y": 70,
      "z": 0,
      "type": "powered_rail",
      "metadata": 0,
      "track_id": 2
    },
    {
      "x": 40,
      "y": 71,
      "z": 0,
      "type": "powered_rail",
      "metadata": 0,
      "track_id": 2
    },
    {
      "x": 40,
      "y": 72,
      "z": 0,
      "type": "powered_rail",
      "metadata": 0,
      "track_id": 2
    },
    {
      "x": 40,
      "y": 73,
      "z": 0,
      "type": "powered_rail",
      "metadata": 0,
      "track_id": 2
    },
    {
      "x": 45,
      "y": 64,
      "z": 0,
      "type": "powered_rail",
      "metadata": 0,
      "track_id": 2
    },
    {
      "x": 44,
      "y": 65,
      "z": 0,
      "type": "powered_rail",
      "metadata": 0,
      "track_id": 2
    },
    {
      "x": 44,
      "y": 66,
      "z": 0,
      "type": "powered_rail",
      "metadata": 0,
      "track_id": 2
    },
    {
      "x": 44,
      "y": 67,
      "z": 0,
      "type": "powered_rail",
      "metadata": 0,
      "track_id": 2
    },
    {
      "x": 43,
      "y": 69,
      "z": 0,
      "type": "powered_rail",
      "metadata": 0,
      "track_id": 2
    },
    {
      "x": 43,
      "y": 70,
      "z": 0,
      "type": "powered_rail",
      "metadata": 0,
      "track_id": 2
    },
    {
      "x": 42,
      "y": 70,
      "z": 0,
      "type": "powered_rail",
      "metadata": 0,
      "track_id": 2
    },
    {
      "x": 41,
      "y": 71,
      "z": 0,
      "type": "powered_rail",
      "metadata": 0,
      "track_id": 2
    },
    {
      "x": 40,
      "y": 71,
      "z": 0,
      "type": "powered_rail",
      "metadata": 0,
      "track_id": 2
    },
    {
      "x": 40,
      "y": 72,
      "z": 0,
      "type": "powered_rail",
      "metadata": 0,
      "track_id": 2
    },
    {
      "x": 40,
      "y": 71,
      "z": 0,
      "type": "powered_rail",
      "metadata": 0,
      "track_id": 2
    },
    {
      "x": 39,
      "y": 71,
      "z": 0,
      "type": "powered_rail",
      "metadata": 0,
      "track_id": 2
    },
    {
      "x": 38,
      "y": 70,
      "z": 0,
      "type": "powered_rail",
      "metadata": 0,
      "track_id": 2
    },
    {
      "x": 37,
      "y": 70,
      "z": 0,
      "type": "powered_rail",
      "metadata": 0,
      "track_id": 2
    },
    {
      "x": 37,
      "y": 69,
      "z": 0,
      "type": "powered_rail",
      "metadata": 0,
      "track_id": 2
    },
    {
      "x": 36,
      "y": 67,
      "z": 0,
      "type": "powered_rail",
      "metadata": 0,
      "track_id": 2
    },
    {
      "x": 36,
      "y": 66,
      "z": 0,
      "type": "powered_rail",
      "metadata": 0,
      "track_id": 2
    },
    {
      "x": 36,
      "y": 65,
      "z": 0,
      "type": "powered_rail",
      "metadata": 0,
      "track_id": 2
    },
    {
      "x": 35,
      "y": 64,
      "z": 0,
      "type": "powered_rail",
      "metadata": 0,
      "track_id": 2
    },
    {
      "x": 36,
      "y": 63,
      "z": 0,
      "type": "powered_rail",
      "metadata": 0,
      "track_id": 2
    },
    {
      "x": 36,
      "y": 62,
      "z": 0,
      "type": "powered_rail",
      "metadata": 0,
      "track_id": 2
    },
    {
      "x": 36,
      "y": 60,
      "z": 0,
      "type": "powered_rail",
      "metadata": 0,
      "track_id": 2
    },
    {
      "x": 37,
      "y": 59,
      "z": 0,
      "type": "powered_rail",
      "metadata": 0,
      "track_id": 2
    },
    {
      "x": 37,
      "y": 58,
      "z": 0,
      "type": "powered_rail",
      "metadata": 0,
      "track_id": 2
    },
    {
      "x": 38,
      "y": 58,
      "z": 0,
      "type": "powered_rail",
      "metadata": 0,
      "track_id": 2
    },
    {
      "x": 39,
      "y": 57,
      "z": 0,
      "type": "powered_rail",
      "metadata": 0,
      "track_id": 2
    },
    {
      "x": 40,
      "y": 57,
      "z": 0,
      "type": "powered_rail",
      "metadata": 0,
      "track_id": 2
    },
    {
      "x": 40,
      "y": 56,
      "z": 0,
      "type": "powered_rail",
      "metadata": 0,
      "track_id": 2
    },
    {
      "x": 40,
      "y": 57,
      "z": 0,
      "type": "powered_rail",
      "metadata": 0,
      "track_id": 2
    },
    {
      "x": 41,
      "y": 57,
      "z": 0,
      "type": "powered_rail",
      "metadata": 0,
      "track_id": 2
    },
    {
      "x": 42,
      "y": 58,
      "z": 0,
      "type": "powered_rail",
      "metadata": 0,
      "track_id": 2
    },
    {
      "x": 43,
      "y": 58,
      "z": 0,
      "type": "powered_rail",
      "metadata": 0,
      "track_id": 2
    },
    {
      "x": 43,
      "y": 59,
      "z": 0,
      "type": "powered_rail",
      "metadata": 0,
      "track_id": 2
    },
    {
      "x": 44,
      "y": 60,
      "z": 0,
      "type": "powered_rail",
      "metadata": 0,
      "track_id": 2
    },
    {
      "x": 44,
      "y": 62,
      "z": 0,
      "type": "powered_rail",
      "metadata": 0,
      "track_id": 2
    },
    {
      "x": 44,
      "y": 63,
      "z": 0,
      "type": "powered_rail",
      "metadata": 0,
      "track_id": 2
    },
    {
      "x": 40,
      "y": 64,
      "z": 0,
      "type": "powered_rail",
      "metadata": 0,
      "track_id": 2
    },
    {
      "x": 40,
      "y": 63,
      "z": 0,
      "type": "powered_rail",
      "metadata": 0,
      "track_id": 2
    },
    {
      "x": 40,
      "y": 62,
      "z": 0,
      "type": "powered_rail",
      "metadata": 0,
      "track_id": 2
    },
    {
      "x": 40,
      "y": 61,
      "z": 0,
      "type": "powered_rail",
      "metadata": 0,
      "track_id": 2
    },
    {
      "x": 40,
      "y": 60,
      "z": 0,
      "type": "powered_rail",
      "metadata": 0,
      "track_id": 2
    },
    {
      "x": 40,
      "y": 59,
      "z": 0,
      "type": "powered_rail",
      "metadata": 0,
      "track_id": 2
    },
    {
      "x": 40,
      "y": 58,
      "z": 0,
      "type": "powered_rail",
      "metadata": 0,
      "track_id": 2
    },
    {
      "x": 40,
      "y": 57,
      "z": 0,
      "type": "powered_rail",
      "metadata": 0,
      "track_id": 2
    },
    {
      "x": 40,
      "y": 56,
      "z": 0,
      "type": "powered_rail",
      "metadata": 0,
      "track_id": 2
    },
    {
      "x": 40,
      "y": 55,
      "z": 0,
      "type": "powered_rail",
      "metadata": 0,
      "track_id": 2
    },
    {
      "x": 40,
      "y": 54,
      "z": 0,
      "type": "powered_rail",
      "metadata": 0,
      "track_id": 2
    },
    {
      "x": 40,
      "y": 53,
      "z": 0,
      "type": "powered_rail",
      "metadata": 0,
      "track_id": 2
    },
    {
      "x": 40,
      "y": 52,
      "z": 0,
      "type": "powered_rail",
      "metadata": 0,
      "track_id": 2
    },
    {
      "x": 40,
      "y": 51,
      "z": 0,
      "type": "powered_rail",
      "metadata": 0,
      "track_id": 2
    },
    {
      "x": 40,
      "y": 50,
      "z": 0,
      "type": "powered_rail",
      "metadata": 0,
      "track_id": 2
    },
    {
      "x": 40,
      "y": 64,
      "z": 0,
      "type": "powered_rail",
      "metadata": 0,
      "track_id": 2
    },
    {
      "x": 41,
      "y": 64,
      "z": 0,
      "type": "powered_rail",
      "metadata": 0,
      "track_id": 2
    },
    {
      "x": 42,
      "y": 64,
      "z": 0,
      "type": "powered_rail",
      "metadata": 0,
      "track_id": 2
    },
    {
      "x": 43,
      "y": 64,
      "z": 0,
      "type": "powered_rail",
      "metadata": 0,
      "track_id": 2
    },
    {
      "x": 44,
      "y": 64,
      "z": 0,
      "type": "powered_rail",
      "metadata": 0,
      "track_id": 2
    },
    {
      "x": 60,
      "y": 64,
      "z": 0,
      "type": "powered_rail",
      "metadata": 0,
      "track_id": 3
    },
    {
      "x": 60,
      "y": 65,
      "z": 0,
      "type": "powered_rail",
      "metadata": 0,
      "track_id": 3
    },
    {
      "x": 60,
      "y": 66,
      "z": 0,
      "type": "powered_rail",
      "metadata": 0,
      "track_id": 3
    },
    {
      "x": 60,
      "y": 67,
      "z": 0,
      "type": "powered_rail",
      "metadata": 0,
      "track_id": 3
    },
    {
      "x": 60,
      "y": 68,
      "z": 0,
      "type": "powered_rail",
      "metadata": 0,
      "track_id": 3
    },
    {
      "x": 60,
      "y": 69,
      "z": 0,
      "type": "powered_rail",
      "metadata": 0,
      "track_id": 3
    },
    {
      "x": 60,
      "y": 70,
      "z": 0,
      "type": "powered_rail",
      "metadata": 0,
      "track_id": 3
    },
    {
      "x": 60,
      "y": 71,
      "z": 0,
      "type": "powered_rail",
      "metadata": 0,
      "track_id": 3
    },
    {
      "x": 60,
      "y": 72,
      "z": 0,
      "type": "powered_rail",
      "metadata": 0,
      "track_id": 3
    },
    {
      "x": 60,
      "y": 73,
      "z": 0,
      "type": "powered_rail",
      "metadata": 0,
      "track_id": 3
    },
    {
      "x": 65,
      "y": 64,
      "z": 0,
      "type": "powered_rail",
      "metadata": 0,
      "track_id": 3
    },
    {
      "x": 64,
      "y": 65,
      "z": 0,
      "type": "powered_rail",
      "metadata": 0,
      "track_id": 3
    },
    {
      "x": 64,
      "y": 66,
      "z": 0,
      "type": "powered_rail",
      "metadata": 0,
      "track_id": 3
    },
    {
      "x": 64,
      "y": 67,
      "z": 0,
      "type": "powered_rail",
      "metadata": 0,
      "track_id": 3
    },
    {
      "x": 63,
      "y": 69,
      "z": 0,
      "type": "powered_rail",
      "metadata": 0,
      "track_id": 3
    },
    {
      "x": 63,
      "y": 70,
      "z": 0,
      "type": "powered_rail",
      "metadata": 0,
      "track_id": 3
    },
    {
      "x": 62,
      "y": 70,
      "z": 0,
      "type": "powered_rail",
      "metadata": 0,
      "track_id": 3
    },
    {
      "x": 61,
      "y": 71,
      "z": 0,
      "type": "powered_rail",
      "metadata": 0,
      "track_id": 3
    },
    {
      "x": 60,
      "y": 71,
      "z": 0,
      "type": "powered_rail",
      "metadata": 0,
      "track_id": 3
    },
    {
      "x": 60,
      "y": 72,
      "z": 0,
      "type": "powered_rail",
      "metadata": 0,
      "track_id": 3
    },
    {
      "x": 60,
      "y": 71,
      "z": 0,
      "type": "powered_rail",
      "metadata": 0,
      "track_id": 3
    },
    {
      "x": 59,
      "y": 71,
      "z": 0,
      "type": "powered_rail",
      "metadata": 0,
      "track_id": 3
    },
    {
      "x": 58,
      "y": 70,
      "z": 0,
      "type": "powered_rail",
      "metadata": 0,
      "track_id": 3
    },
    {
      "x": 57,
      "y": 70,
      "z": 0,
      "type": "powered_rail",
      "metadata": 0,
      "track_id": 3
    },
    {
      "x": 57,
      "y": 69,
      "z": 0,
      "type": "powered_rail",
      "metadata": 0,
      "track_id": 3
    },
    {
      "x": 56,
      "y": 67,
      "z": 0,
      "type": "powered_rail",
      "metadata": 0,
      "track_id": 3
    },
    {
      "x": 56,
      "y": 66,
      "z": 0,
      "type": "powered_rail",
      "metadata": 0,
      "track_id": 3
    },
    {
      "x": 56,
      "y": 65,
      "z": 0,
      "type": "powered_rail",
      "metadata": 0,
      "track_id": 3
    },
    {
      "x": 55,
      "y": 64,
      "z": 0,
      "type": "powered_rail",
      "metadata": 0,
      "track_id": 3
    },
    {
      "x": 56,
      "y": 63,
      "z": 0,
      "type": "powered_rail",
      "metadata": 0,
      "track_id": 3
    },
    {
      "x": 56,
      "y": 62,
      "z": 0,
      "type": "powered_rail",
      "metadata": 0,
      "track_id": 3
    },
    {
      "x": 56,
      "y": 60,
      "z": 0,
      "type": "powered_rail",
      "metadata": 0,
      "track_id": 3
    },
    {
      "x": 57,
      "y": 59,
      "z": 0,
      "type": "powered_rail",
      "metadata": 0,
      "track_id": 3
    },
    {
      "x": 57,
      "y": 58,
      "z": 0,
      "type": "powered_rail",
      "metadata": 0,
      "track_id": 3
    },
    {
      "x": 58,
      "y": 58,
      "z": 0,
      "type": "powered_rail",
      "metadata": 0,
      "track_id": 3
    },
    {
      "x": 59,
      "y": 57,
      "z": 0,
      "type": "powered_rail",
      "metadata": 0,
      "track_id": 3
    },
    {
      "x": 60,
      "y": 57,
      "z": 0,
      "type": "powered_rail",
      "metadata": 0,
      "track_id": 3
    },
    {
      "x": 60,
      "y": 56,
      "z": 0,
      "type": "powered_rail",
      "metadata": 0,
      "track_id": 3
    },
    {
      "x": 60,
      "y": 57,
      "z": 0,
      "type": "powered_rail",
      "metadata": 0,
      "track_id": 3
    },
    {
      "x": 61,
      "y": 57,
      "z": 0,
      "type": "powered_rail",
      "metadata": 0,
      "track_id": 3
    },
    {
      "x": 62,
      "y": 58,
      "z": 0,
      "type": "powered_rail",
      "metadata": 0,
      "track_id": 3
    },
    {
      "x": 63,
      "y": 58,
      "z": 0,
      "type": "powered_rail",
      "metadata": 0,
      "track_id": 3
    },
    {
      "x": 63,
      "y": 59,
      "z": 0,
      "type": "powered_rail",
      "metadata": 0,
      "track_id": 3
    },
    {
      "x": 64,
      "y": 60,
      "z": 0,
      "type": "powered_rail",
      "metadata": 0,
      "track_id": 3
    },
    {
      "x": 64,
      "y": 62,
      "z": 0,
      "type": "powered_rail",
      "metadata": 0,
      "track_id": 3
    },
    {
      "x": 64,
      "y": 63,
      "z": 0,
      "type": "powered_rail",
      "metadata": 0,
      "track_id": 3
    },
    {
      "x": 60,
      "y": 64,
      "z": 0,
      "type": "powered_rail",
      "metadata": 0,
      "track_id": 3
    },
    {
      "x": 60,
      "y": 63,
      "z": 0,
      "type": "powered_rail",
      "metadata": 0,
      "track_id": 3
    },
    {
      "x": 60,
      "y": 62,
      "z": 0,
      "type": "powered_rail",
      "metadata": 0,
      "track_id": 3
    },
    {
      "x": 60,
      "y": 61,
      "z": 0,
      "type": "powered_rail",
      "metadata": 0,
      "track_id": 3
    },
    {
      "x": 60,
      "y": 60,
      "z": 0,
      "type": "powered_rail",
      "metadata": 0,
      "track_id": 3
    },
    {
      "x": 60,
      "y": 59,
      "z": 0,
      "type": "powered_rail",
      "metadata": 0,
      "track_id": 3
    },
    {
      "x": 60,
      "y": 58,
      "z": 0,
      "type": "powered_rail",
      "metadata": 0,
      "track_id": 3
    },
    {
      "x": 60,
      "y": 57,
      "z": 0,
      "type": "powered_rail",
      "metadata": 0,
      "track_id": 3
    },
    {
      "x": 60,
      "y": 56,
      "z": 0,
      "type": "powered_rail",
      "metadata": 0,
      "track_id": 3
    },
    {
      "x": 60,
      "y": 55,
      "z": 0,
      "type": "powered_rail",
      "metadata": 0,
      "track_id": 3
    },
    {
      "x": 60,
      "y": 54,
      "z": 0,
      "type": "powered_rail",
      "metadata": 0,
      "track_id": 3
    },
    {
      "x": 60,
      "y": 53,
      "z": 0,
      "type": "powered_rail",
      "metadata": 0,
      "track_id": 3
    },
    {
      "x": 60,
      "y": 52,
      "z": 0,
      "type": "powered_rail",
      "metadata": 0,
      "track_id": 3
    },
    {
      "x": 60,
      "y": 51,
      "z": 0,
      "type": "powered_rail",
      "metadata": 0,
      "track_id": 3
    },
    {
      "x": 60,
      "y": 50,
      "z": 0,
      "type": "powered_rail",
      "metadata": 0,
      "track_id": 3
    },
    {
      "x": 60,
      "y": 64,
      "z": 0,
      "type": "powered_rail",
      "metadata": 0,
      "track_id": 3
    },
    {
      "x": 61,
      "y": 64,
      "z": 0,
      "type": "powered_rail",
      "metadata": 0,
      "track_id": 3
    },
    {
      "x": 62,
      "y": 64,
      "z": 0,
      "type": "powered_rail",
      "metadata": 0,
      "track_id": 3
    },
    {
      "x": 63,
      "y": 64,
      "z": 0,
      "type": "powered_rail",
      "metadata": 0,
      "track_id": 3
    },
    {
      "x": 64,
      "y": 64,
      "z": 0,
      "type": "powered_rail",
      "metadata": 0,
      "track_id": 3
    },
    {
      "x": 80,
      "y": 64,
      "z": 0,
      "type": "powered_rail",
      "metadata": 0,
      "track_id": 4
    },
    {
      "x": 80,
      "y": 65,
      "z": 0,
      "type": "powered_rail",
      "metadata": 0,
      "track_id": 4
    },
    {
      "x": 80,
      "y": 66,
      "z": 0,
      "type": "powered_rail",
      "metadata": 0,
      "track_id": 4
    },
    {
      "x": 80,
      "y": 67,
      "z": 0,
      "type": "powered_rail",
      "metadata": 0,
      "track_id": 4
    },
    {
      "x": 80,
      "y": 68,
      "z": 0,
      "type": "powered_rail",
      "metadata": 0,
      "track_id": 4
    },
    {
      "x": 80,
      "y": 69,
      "z": 0,
      "type": "powered_rail",
      "metadata": 0,
      "track_id": 4
    },
    {
      "x": 80,
      "y": 70,
      "z": 0,
      "type": "powered_rail",
      "metadata": 0,
      "track_id": 4
    },
    {
      "x": 80,
      "y": 71,
      "z": 0,
      "type": "powered_rail",
      "metadata": 0,
      "track_id": 4
    },
    {
      "x": 80,
      "y": 72,
      "z": 0,
      "type": "powered_rail",
      "metadata": 0,
      "track_id": 4
    },
    {
      "x": 80,
      "y": 73,
      "z": 0,
      "type": "powered_rail",
      "metadata": 0,
      "track_id": 4
    },
    {
      "x": 85,
      "y": 64,
      "z": 0,
      "type": "powered_rail",
      "metadata": 0,
      "track_id": 4
    },
    {
      "x": 84,
      "y": 65,
      "z": 0,
      "type": "powered_rail",
      "metadata": 0,
      "track_id": 4
    },
    {
      "x": 84,
      "y": 66,
      "z": 0,
      "type": "powered_rail",
      "metadata": 0,
      "track_id": 4
    },
    {
      "x": 84,
      "y": 67,
      "z": 0,
      "type": "powered_rail",
      "metadata": 0,
      "track_id": 4
    },
    {
      "x": 83,
      "y": 69,
      "z": 0,
      "type": "powered_rail",
      "metadata": 0,
      "track_id": 4
    },
    {
      "x": 83,
      "y": 70,
      "z": 0,
      "type": "powered_rail",
      "metadata": 0,
      "track_id": 4
    },
    {
      "x": 82,
      "y": 70,
      "z": 0,
      "type": "powered_rail",
      "metadata": 0,
      "track_id": 4
    },
    {
      "x": 81,
      "y": 71,
      "z": 0,
      "type": "powered_rail",
      "metadata": 0,
      "track_id": 4
    },
    {
      "x": 80,
      "y": 71,
      "z": 0,
      "type": "powered_rail",
      "metadata": 0,
      "track_id": 4
    },
    {
      "x": 80,
      "y": 72,
      "z": 0,
      "type": "powered_rail",
      "metadata": 0,
      "track_id": 4
    },
    {
      "x": 80,
      "y": 71,
      "z": 0,
      "type": "powered_rail",
      "metadata": 0,
      "track_id": 4
    },
    {
      "x": 79,
      "y": 71,
      "z": 0,
      "type": "powered_rail",
      "metadata": 0,
      "track_id": 4
    },
    {
      "x": 78,
      "y": 70,
      "z": 0,
      "type": "powered_rail",
      "metadata": 0,
      "track_id": 4
    },
    {
      "x": 77,
      "y": 70,
      "z": 0,
      "type": "powered_rail",
      "metadata": 0,
      "track_id": 4
    },
    {
      "x": 77,
      "y": 69,
      "z": 0,
      "type": "powered_rail",
      "metadata": 0,
      "track_id": 4
    },
    {
      "x": 76,
      "y": 67,
      "z": 0,
      "type": "powered_rail",
      "metadata": 0,
      "track_id": 4
    },
    {
      "x": 76,
      "y": 66,
      "z": 0,
      "type": "powered_rail",
      "metadata": 0,
      "track_id": 4
    },
    {
      "x": 76,
      "y": 65,
      "z": 0,
      "type": "powered_rail",
      "metadata": 0,
      "track_id": 4
    },
    {
      "x": 75,
      "y": 64,
      "z": 0,
      "type": "powered_rail",
      "metadata": 0,
      "track_id": 4
    },
    {
      "x": 76,
      "y": 63,
      "z": 0,
      "type": "powered_rail",
      "metadata": 0,
      "track_id": 4
    },
    {
      "x": 76,
      "y": 62,
      "z": 0,
      "type": "powered_rail",
      "metadata": 0,
      "track_id": 4
    },
    {
      "x": 76,
      "y": 60,
      "z": 0,
      "type": "powered_rail",
      "metadata": 0,
      "track_id": 4
    },
    {
      "x": 77,
      "y": 59,
      "z": 0,
      "type": "powered_rail",
      "metadata": 0,
      "track_id": 4
    },
    {
      "x": 77,
      "y": 58,
      "z": 0,
      "type": "powered_rail",
      "metadata": 0,
      "track_id": 4
    },
    {
      "x": 78,
      "y": 58,
      "z": 0,
      "type": "powered_rail",
      "metadata": 0,
      "track_id": 4
    },
    {
      "x": 79,
      "y": 57,
      "z": 0,
      "type": "powered_rail",
      "metadata": 0,
      "track_id": 4
    },
    {
      "x": 80,
      "y": 57,
      "z": 0,
      "type": "powered_rail",
      "metadata": 0,
      "track_id": 4
    },
    {
      "x": 80,
      "y": 56,
      "z": 0,
      "type": "powered_rail",
      "metadata": 0,
      "track_id": 4
    },
    {
      "x": 80,
      "y": 57,
      "z": 0,
      "type": "powered_rail",
      "metadata": 0,
      "track_id": 4
    },
    {
      "x": 81,
      "y": 57,
      "z": 0,
      "type": "powered_rail",
      "metadata": 0,
      "track_id": 4
    },
    {
      "x": 82,
      "y": 58,
      "z": 0,
      "type": "powered_rail",
      "metadata": 0,
      "track_id": 4
    },
    {
      "x": 83,
      "y": 58,
      "z": 0,
      "type": "powered_rail",
      "metadata": 0,
      "track_id": 4
    },
    {
      "x": 83,
      "y": 59,
      "z": 0,
      "type": "powered_rail",
      "metadata": 0,
      "track_id": 4
    },
    {
      "x": 84,
      "y": 60,
      "z": 0,
      "type": "powered_rail",
      "metadata": 0,
      "track_id": 4
    },
    {
      "x": 84,
      "y": 62,
      "z": 0,
      "type": "powered_rail",
      "metadata": 0,
      "track_id": 4
    },
    {
      "x": 84,
      "y": 63,
      "z": 0,
      "type": "powered_rail",
      "metadata": 0,
      "track_id": 4
    },
    {
      "x": 80,
      "y": 64,
      "z": 0,
      "type": "powered_rail",
      "metadata": 0,
      "track_id": 4
    },
    {
      "x": 80,
      "y": 63,
      "z": 0,
      "type": "powered_rail",
      "metadata": 0,
      "track_id": 4
    },
    {
      "x": 80,
      "y": 62,
      "z": 0,
      "type": "powered_rail",
      "metadata": 0,
      "track_id": 4
    },
    {
      "x": 80,
      "y": 61,
      "z": 0,
      "type": "powered_rail",
      "metadata": 0,
      "track_id": 4
    },
    {
      "x": 80,
      "y": 60,
      "z": 0,
      "type": "powered_rail",
      "metadata": 0,
      "track_id": 4
    },
    {
      "x": 80,
      "y": 59,
      "z": 0,
      "type": "powered_rail",
      "metadata": 0,
      "track_id": 4
    },
    {
      "x": 80,
      "y": 58,
      "z": 0,
      "type": "powered_rail",
      "metadata": 0,
      "track_id": 4
    },
    {
      "x": 80,
      "y": 57,
      "z": 0,
      "type": "powered_rail",
      "metadata": 0,
      "track_id": 4
    },
    {
      "x": 80,
      "y": 56,
      "z": 0,
      "type": "powered_rail",
      "metadata": 0,
      "track_id": 4
    },
    {
      "x": 80,
      "y": 55,
      "z": 0,
      "type": "powered_rail",
      "metadata": 0,
      "track_id": 4
    },
    {
      "x": 80,
      "y": 54,
      "z": 0,
      "type": "powered_rail",
      "metadata": 0,
      "track_id": 4
    },
    {
      "x": 80,
      "y": 53,
      "z": 0,
      "type": "powered_rail",
      "metadata": 0,
      "track_id": 4
    },
    {
      "x": 80,
      "y": 52,
      "z": 0,
      "type": "powered_rail",
      "metadata": 0,
      "track_id": 4
    },
    {
      "x": 80,
      "y": 51,
      "z": 0,
      "type": "powered_rail",
      "metadata": 0,
      "track_id": 4
    },
    {
      "x": 80,
      "y": 50,
      "z": 0,
      "type": "powered_rail",
      "metadata": 0,
      "track_id": 4
    },
    {
      "x": 80,
      "y": 64,
      "z": 0,
      "type": "powered_rail",
      "metadata": 0,
      "track_id": 4
    },
    {
      "x": 81,
      "y": 64,
      "z": 0,
      "type": "powered_rail",
      "metadata": 0,
      "track_id": 4
    },
    {
      "x": 82,
      "y": 64,
      "z": 0,
      "type": "powered_rail",
      "metadata": 0,
      "track_id": 4
    },
    {
      "x": 83,
      "y": 64,
      "z": 0,
      "type": "powered_rail",
      "metadata": 0,
      "track_id": 4
    },
    {
      "x": 84,
      "y": 64,
      "z": 0,
      "type": "powered_rail",
      "metadata": 0,
      "track_id": 4
    }
  ],
  "decorations": [
    {
      "x": -5,
      "y": 63,
      "z": -5,
      "type": "stone_bricks",
      "metadata": 0
    },
    {
      "x": -5,
      "y": 63,
      "z": -4,
      "type": "stone_bricks",
      "metadata": 0
    },
    {
      "x": -5,
      "y": 63,
      "z": -3,
      "type": "stone_bricks",
      "metadata": 0
    },
    {
      "x": -5,
      "y": 63,
      "z": -2,
      "type": "stone_bricks",
      "metadata": 0
    },
    {
      "x": -5,
      "y": 63,
      "z": -1,
      "type": "stone_bricks",
      "metadata": 0
    },
    {
      "x": -5,
      "y": 63,
      "z": 0,
      "type": "stone_bricks",
      "metadata": 0
    },
    {
      "x": -5,
      "y": 63,
      "z": 1,
      "type": "stone_bricks",
      "metadata": 0
    },
    {
      "x": -5,
      "y": 63,
      "z": 2,
      "type": "stone_bricks",
      "metadata": 0
    },
    {
      "x": -5,
      "y": 63,
      "z": 3,
      "type": "stone_bricks",
      "metadata": 0
    },
    {
      "x": -5,
      "y": 63,
      "z": 4,
      "type": "stone_bricks",
      "metadata": 0
    },
    {
      "x": -4,
      "y": 63,
      "z": -5,
      "type": "stone_bricks",
      "metadata": 0
    },
    {
      "x": -4,
      "y": 63,
      "z": -4,
      "type": "stone_bricks",
      "metadata": 0
    },
    {
      "x": -4,
      "y": 63,
      "z": -3,
      "type": "stone_bricks",
      "metadata": 0
    },
    {
      "x": -4,
      "y": 63,
      "z": -2,
      "type": "stone_bricks",
      "metadata": 0
    },
    {
      "x": -4,
      "y": 63,
      "z": -1,
      "type": "stone_bricks",
      "metadata": 0
    },
    {
      "x": -4,
      "y": 63,
      "z": 0,
      "type": "stone_bricks",
      "metadata": 0
    },
    {
      "x": -4,
      "y": 63,
      "z": 1,
      "type": "stone_bricks",
      "metadata": 0
    },
    {
      "x": -4,
      "y": 63,
      "z": 2,
      "type": "stone_bricks",
      "metadata": 0
    },
    {
      "x": -4,
      "y": 63,
      "z": 3,
      "type": "stone_bricks",
      "metadata": 0
    },
    {
      "x": -4,
      "y": 63,
      "z": 4,
      "type": "stone_bricks",
      "metadata": 0
    },
    {
      "x": -3,
      "y": 63,
      "z": -5,
      "type": "stone_bricks",
      "metadata": 0
    },
    {
      "x": -3,
      "y": 63,
      "z": -4,
      "type": "stone_bricks",
      "metadata": 0
    },
    {
      "x": -3,
      "y": 63,
      "z": -3,
      "type": "stone_bricks",
      "metadata": 0
    },
    {
      "x": -3,
      "y": 63,
      "z": -2,
      "type": "stone_bricks",
      "metadata": 0
    },
    {
      "x": -3,
      "y": 63,
      "z": -1,
      "type": "stone_bricks",
      "metadata": 0
    },
    {
      "x": -3,
      "y": 63,
      "z": 0,
      "type": "stone_bricks",
      "metadata": 0
    },
    {
      "x": -3,
      "y": 63,
      "z": 1,
      "type": "stone_bricks",
      "metadata": 0
    },
    {
      "x": -3,
      "y": 63,
      "z": 2,
      "type": "stone_bricks",
      "metadata": 0
    },
    {
      "x": -3,
      "y": 63,
      "z": 3,
      "type": "stone_bricks",
      "metadata": 0
    },
    {
      "x": -3,
      "y": 63,
      "z": 4,
      "type": "stone_bricks",
      "metadata": 0
    },
    {
      "x": -2,
      "y": 63,
      "z": -5,
      "type": "stone_bricks",
      "metadata": 0
    },
    {
      "x": -2,
      "y": 63,
      "z": -4,
      "type": "stone_bricks",
      "metadata": 0
    },
    {
      "x": -2,
      "y": 63,
      "z": -3,
      "type": "stone_bricks",
      "metadata": 0
    },
    {
      "x": -2,
      "y": 63,
      "z": -2,
      "type": "stone_bricks",
      "metadata": 0
    },
    {
      "x": -2,
      "y": 63,
      "z": -1,
      "type": "stone_bricks",
      "metadata": 0
    },
    {
      "x": -2,
      "y": 63,
      "z": 0,
      "type": "stone_bricks",
      "metadata": 0
    },
    {
      "x": -2,
      "y": 63,
      "z": 1,
      "type": "stone_bricks",
      "metadata": 0
    },
    {
      "x": -2,
      "y": 63,
      "z": 2,
      "type": "stone_bricks",
      "metadata": 0
    },
    {
      "x": -2,
      "y": 63,
      "z": 3,
      "type": "stone_bricks",
      "metadata": 0
    },
    {
      "x": -2,
      "y": 63,
      "z": 4,
      "type": "stone_bricks",
      "metadata": 0
    },
    {
      "x": -1,
      "y": 63,
      "z": -5,
      "type": "stone_bricks",
      "metadata": 0
    },
    {
      "x": -1,
      "y": 63,
      "z": -4,
      "type": "stone_bricks",
      "metadata": 0
    },
    {
      "x": -1,
      "y": 63,
      "z": -3,
      "type": "stone_bricks",
      "metadata": 0
    },
    {
      "x": -1,
      "y": 63,
      "z": -2,
      "type": "stone_bricks",
      "metadata": 0
    },
    {
      "x": -1,
      "y": 63,
      "z": -1,
      "type": "stone_bricks",
      "metadata": 0
    },
    {
      "x": -1,
      "y": 63,
      "z": 0,
      "type": "stone_bricks",
      "metadata": 0
    },
    {
      "x": -1,
      "y": 63,
      "z": 1,
      "type": "stone_bricks",
      "metadata": 0
    },
    {
      "x": -1,
      "y": 63,
      "z": 2,
      "type": "stone_bricks",
      "metadata": 0
    },
    {
      "x": -1,
      "y": 63,
      "z": 3,
      "type": "stone_bricks",
      "metadata": 0
    },
    {
      "x": -1,
      "y": 63,
      "z": 4,
      "type": "stone_bricks",
      "metadata": 0
    },
    {
      "x": 0,
      "y": 63,
      "z": -5,
      "type": "stone_bricks",
      "metadata": 0
    },
    {
      "x": 0,
      "y": 63,
      "z": -4,
      "type": "stone_bricks",
      "metadata": 0
    },
    {
      "x": 0,
      "y": 63,
      "z": -3,
      "type": "stone_bricks",
      "metadata": 0
    },
    {
      "x": 0,
      "y": 63,
      "z": -2,
      "type": "stone_bricks",
      "metadata": 0
    },
    {
      "x": 0,
      "y": 63,
      "z": -1,
      "type": "stone_bricks",
      "metadata": 0
    },
    {
      "x": 0,
      "y": 63,
      "z": 0,
      "type": "stone_bricks",
      "metadata": 0
    },
    {
      "x": 0,
      "y": 63,
      "z": 1,
      "type": "stone_bricks",
      "metadata": 0
    },
    {
      "x": 0,
      "y": 63,
      "z": 2,
      "type": "stone_bricks",
      "metadata": 0
    },
    {
      "x": 0,
      "y": 63,
      "z": 3,
      "type": "stone_bricks",
      "metadata": 0
    },
    {
      "x": 0,
      "y": 63,
      "z": 4,
      "type": "stone_bricks",
      "metadata": 0
    },
    {
      "x": 1,
      "y": 63,
      "z": -5,
      "type": "stone_bricks",
      "metadata": 0
    },
    {
      "x": 1,
      "y": 63,
      "z": -4,
      "type": "stone_bricks",
      "metadata": 0
    },
    {
      "x": 1,
      "y": 63,
      "z": -3,
      "type": "stone_bricks",
      "metadata": 0
    },
    {
      "x": 1,
      "y": 63,
      "z": -2,
      "type": "stone_bricks",
      "metadata": 0
    },
    {
      "x": 1,
      "y": 63,
      "z": -1,
      "type": "stone_bricks",
      "metadata": 0
    },
    {
      "x": 1,
      "y": 63,
      "z": 0,
      "type": "stone_bricks",
      "metadata": 0
    },
    {
      "x": 1,
      "y": 63,
      "z": 1,
      "type": "stone_bricks",
      "metadata": 0
    },
    {
      "x": 1,
      "y": 63,
      "z": 2,
      "type": "stone_bricks",
      "metadata": 0
    },
    {
      "x": 1,
      "y": 63,
      "z": 3,
      "type": "stone_bricks",
      "metadata": 0
    },
    {
      "x": 1,
      "y": 63,
      "z": 4,
      "type": "stone_bricks",
      "metadata": 0
    },
    {
      "x": 2,
      "y": 63,
      "z": -5,
      "type": "stone_bricks",
      "metadata": 0
    },
    {
      "x": 2,
      "y": 63,
      "z": -4,
      "type": "stone_bricks",
      "metadata": 0
    },
    {
      "x": 2,
      "y": 63,
      "z": -3,
      "type": "stone_bricks",
      "metadata": 0
    },
    {
      "x": 2,
      "y": 63,
      "z": -2,
      "type": "stone_bricks",
      "metadata": 0
    },
    {
      "x": 2,
      "y": 63,
      "z": -1,
      "type": "stone_bricks",
      "metadata": 0
    },
    {
      "x": 2,
      "y": 63,
      "z": 0,
      "type": "stone_bricks",
      "metadata": 0
    },
    {
      "x": 2,
      "y": 63,
      "z": 1,
      "type": "stone_bricks",
      "metadata": 0
    },
    {
      "x": 2,
      "y": 63,
      "z": 2,
      "type": "stone_bricks",
      "metadata": 0
    },
    {
      "x": 2,
      "y": 63,
      "z": 3,
      "type": "stone_bricks",
      "metadata": 0
    },
    {
      "x": 2,
      "y": 63,
      "z": 4,
      "type": "stone_bricks",
      "metadata": 0
    },
    {
      "x": 3,
      "y": 63,
      "z": -5,
      "type": "stone_bricks",
      "metadata": 0
    },
    {
      "x": 3,
      "y": 63,
      "z": -4,
      "type": "stone_bricks",
      "metadata": 0
    },
    {
      "x": 3,
      "y": 63,
      "z": -3,
      "type": "stone_bricks",
      "metadata": 0
    },
    {
      "x": 3,
      "y": 63,
      "z": -2,
      "type": "stone_bricks",
      "metadata": 0
    },
    {
      "x": 3,
      "y": 63,
      "z": -1,
      "type": "stone_bricks",
      "metadata": 0
    },
    {
      "x": 3,
      "y": 63,
      "z": 0,
      "type": "stone_bricks",
      "metadata": 0
    },
    {
      "x": 3,
      "y": 63,
      "z": 1,
      "type": "stone_bricks",
      "metadata": 0
    },
    {
      "x": 3,
      "y": 63,
      "z": 2,
      "type": "stone_bricks",
      "metadata": 0
    },
    {
      "x": 3,
      "y": 63,
      "z": 3,
      "type": "stone_bricks",
      "metadata": 0
    },
    {
      "x": 3,
      "y": 63,
      "z": 4,
      "type": "stone_bricks",
      "metadata": 0
    },
    {
      "x": 4,
      "y": 63,
      "z": -5,
      "type": "stone_bricks",
      "metadata": 0
    },
    {
      "x": 4,
      "y": 63,
      "z": -4,
      "type": "stone_bricks",
      "metadata": 0
    },
    {
      "x": 4,
      "y": 63,
      "z": -3,
      "type": "stone_bricks",
      "metadata": 0
    },
    {
      "x": 4,
      "y": 63,
      "z": -2,
      "type": "stone_bricks",
      "metadata": 0
    },
    {
      "x": 4,
      "y": 63,
      "z": -1,
      "type": "stone_bricks",
      "metadata": 0
    },
    {
      "x": 4,
      "y": 63,
      "z": 0,
      "type": "stone_bricks",
      "metadata": 0
    },
    {
      "x": 4,
      "y": 63,
      "z": 1,
      "type": "stone_bricks",
      "metadata": 0
    },
    {
      "x": 4,
      "y": 63,
      "z": 2,
      "type": "stone_bricks",
      "metadata": 0
    },
    {
      "x": 4,
      "y": 63,
      "z": 3,
      "type": "stone_bricks",
      "metadata": 0
    },
    {
      "x": 4,
      "y": 63,
      "z": 4,
      "type": "stone_bricks",
      "metadata": 0
    },
    {
      "x": 5,
      "y": 63,
      "z": -5,
      "type": "stone_bricks",
      "metadata": 0
    },
    {
      "x": 5,
      "y": 63,
      "z": -4,
      "type": "stone_bricks",
      "metadata": 0
    },
    {
      "x": 5,
      "y": 63,
      "z": -3,
      "type": "stone_bricks",
      "metadata": 0
    },
    {
      "x": 5,
      "y": 63,
      "z": -2,
      "type": "stone_bricks",
      "metadata": 0
    },
    {
      "x": 5,
      "y": 63,
      "z": -1,
      "type": "stone_bricks",
      "metadata": 0
    },
    {
      "x": 5,
      "y": 63,
      "z": 0,
      "type": "stone_bricks",
      "metadata": 0
    },
    {
      "x": 5,
      "y": 63,
      "z": 1,
      "type": "stone_bricks",
      "metadata": 0
    },
    {
      "x": 5,
      "y": 63,
      "z": 2,
      "type": "stone_bricks",
      "metadata": 0
    },
    {
      "x": 5,
      "y": 63,
      "z": 3,
      "type": "stone_bricks",
      "metadata": 0
    },
    {
      "x": 5,
      "y": 63,
      "z": 4,
      "type": "stone_bricks",
      "metadata": 0
    },
    {
      "x": 6,
      "y": 63,
      "z": -5,
      "type": "stone_bricks",
      "metadata": 0
    },
    {
      "x": 6,
      "y": 63,
      "z": -4,
      "type": "stone_bricks",
      "metadata": 0
    },
    {
      "x": 6,
      "y": 63,
      "z": -3,
      "type": "stone_bricks",
      "metadata": 0
    },
    {
      "x": 6,
      "y": 63,
      "z": -2,
      "type": "stone_bricks",
      "metadata": 0
    },
    {
      "x": 6,
      "y": 63,
      "z": -1,
      "type": "stone_bricks",
      "metadata": 0
    },
    {
      "x": 6,
      "y": 63,
      "z": 0,
      "type": "stone_bricks",
      "metadata": 0
    },
    {
      "x": 6,
      "y": 63,
      "z": 1,
      "type": "stone_bricks",
      "metadata": 0
    },
    {
      "x": 6,
      "y": 63,
      "z": 2,
      "type": "stone_bricks",
      "metadata": 0
    },
    {
      "x": 6,
      "y": 63,
      "z": 3,
      "type": "stone_bricks",
      "metadata": 0
    },
    {
      "x": 6,
      "y": 63,
      "z": 4,
      "type": "stone_bricks",
      "metadata": 0
    },
    {
      "x": 7,
      "y": 63,
      "z": -5,
      "type": "stone_bricks",
      "metadata": 0
    },
    {
      "x": 7,
      "y": 63,
      "z": -4,
      "type": "stone_bricks",
      "metadata": 0
    },
    {
      "x": 7,
      "y": 63,
      "z": -3,
      "type": "stone_bricks",
      "metadata": 0
    },
    {
      "x": 7,
      "y": 63,
      "z": -2,
      "type": "stone_bricks",
      "metadata": 0
    },
    {
      "x": 7,
      "y": 63,
      "z": -1,
      "type": "stone_bricks",
      "metadata": 0
    },
    {
      "x": 7,
      "y": 63,
      "z": 0,
      "type": "stone_bricks",
      "metadata": 0
    },
    {
      "x": 7,
      "y": 63,
      "z": 1,
      "type": "stone_bricks",
      "metadata": 0
    },
    {
      "x": 7,
      "y": 63,
      "z": 2,
      "type": "stone_bricks",
      "metadata": 0
    },
    {
      "x": 7,
      "y": 63,
      "z": 3,
      "type": "stone_bricks",
      "metadata": 0
    },
    {
      "x": 7,
      "y": 63,
      "z": 4,
      "type": "stone_bricks",
      "metadata": 0
    },
    {
      "x": 8,
      "y": 63,
      "z": -5,
      "type": "stone_bricks",
      "metadata": 0
    },
    {
      "x": 8,
      "y": 63,
      "z": -4,
      "type": "stone_bricks",
      "metadata": 0
    },
    {
      "x": 8,
      "y": 63,
      "z": -3,
      "type": "stone_bricks",
      "metadata": 0
    },
    {
      "x": 8,
      "y": 63,
      "z": -2,
      "type": "stone_bricks",
      "metadata": 0
    },
    {
      "x": 8,
      "y": 63,
      "z": -1,
      "type": "stone_bricks",
      "metadata": 0
    },
    {
      "x": 8,
      "y": 63,
      "z": 0,
      "type": "stone_bricks",
      "metadata": 0
    },
    {
      "x": 8,
      "y": 63,
      "z": 1,
      "type": "stone_bricks",
      "metadata": 0
    },
    {
      "x": 8,
      "y": 63,
      "z": 2,
      "type": "stone_bricks",
      "metadata": 0
    },
    {
      "x": 8,
      "y": 63,
      "z": 3,
      "type": "stone_bricks",
      "metadata": 0
    },
    {
      "x": 8,
      "y": 63,
      "z": 4,
      "type": "stone_bricks",
      "metadata": 0
    },
    {
      "x": 9,
      "y": 63,
      "z": -5,
      "type": "stone_bricks",
      "metadata": 0
    },
    {
      "x": 9,
      "y": 63,
      "z": -4,
      "type": "stone_bricks",
      "metadata": 0
    },
    {
      "x": 9,
      "y": 63,
      "z": -3,
      "type": "stone_bricks",
      "metadata": 0
    },
    {
      "x": 9,
      "y": 63,
      "z": -2,
      "type": "stone_bricks",
      "metadata": 0
    },
    {
      "x": 9,
      "y": 63,
      "z": -1,
      "type": "stone_bricks",
      "metadata": 0
    },
    {
      "x": 9,
      "y": 63,
      "z": 0,
      "type": "stone_bricks",
      "metadata": 0
    },
    {
      "x": 9,
      "y": 63,
      "z": 1,
      "type": "stone_bricks",
      "metadata": 0
    },
    {
      "x": 9,
      "y": 63,
      "z": 2,
      "type": "stone_bricks",
      "metadata": 0
    },
    {
      "x": 9,
      "y": 63,
      "z": 3,
      "type": "stone_bricks",
      "metadata": 0
    },
    {
      "x": 9,
      "y": 63,
      "z": 4,
      "type": "stone_bricks",
      "metadata": 0
    },
    {
      "x": 10,
      "y": 63,
      "z": -5,
      "type": "stone_bricks",
      "metadata": 0
    },
    {
      "x": 10,
      "y": 63,
      "z": -4,
      "type": "stone_bricks",
      "metadata": 0
    },
    {
      "x": 10,
      "y": 63,
      "z": -3,
      "type": "stone_bricks",
      "metadata": 0
    },
    {
      "x": 10,
      "y": 63,
      "z": -2,
      "type": "stone_bricks",
      "metadata": 0
    },
    {
      "x": 10,
      "y": 63,
      "z": -1,
      "type": "stone_bricks",
      "metadata": 0
    },
    {
      "x": 10,
      "y": 63,
      "z": 0,
      "type": "stone_bricks",
      "metadata": 0
    },
    {
      "x": 10,
      "y": 63,
      "z": 1,
      "type": "stone_bricks",
      "metadata": 0
    },
    {
      "x": 10,
      "y": 63,
      "z": 2,
      "type": "stone_bricks",
      "metadata": 0
    },
    {
      "x": 10,
      "y": 63,
      "z": 3,
      "type": "stone_bricks",
      "metadata": 0
    },
    {
      "x": 10,
      "y": 63,
      "z": 4,
      "type": "stone_bricks",
      "metadata": 0
    },
    {
      "x": 11,
      "y": 63,
      "z": -5,
      "type": "stone_bricks",
      "metadata": 0
    },
    {
      "x": 11,
      "y": 63,
      "z": -4,
      "type": "stone_bricks",
      "metadata": 0
    },
    {
      "x": 11,
      "y": 63,
      "z": -3,
      "type": "stone_bricks",
      "metadata": 0
    },
    {
      "x": 11,
      "y": 63,
      "z": -2,
      "type": "stone_bricks",
      "metadata": 0
    },
    {
      "x": 11,
      "y": 63,
      "z": -1,
      "type": "stone_bricks",
      "metadata": 0
    },
    {
      "x": 11,
      "y": 63,
      "z": 0,
      "type": "stone_bricks",
      "metadata": 0
    },
    {
      "x": 11,
      "y": 63,
      "z": 1,
      "type": "stone_bricks",
      "metadata": 0
    },
    {
      "x": 11,
      "y": 63,
      "z": 2,
      "type": "stone_bricks",
      "metadata": 0
    },
    {
      "x": 11,
      "y": 63,
      "z": 3,
      "type": "stone_bricks",
      "metadata": 0
    },
    {
      "x": 11,
      "y": 63,
      "z": 4,
      "type": "stone_bricks",
      "metadata": 0
    },
    {
      "x": 12,
      "y": 63,
      "z": -5,
      "type": "stone_bricks",
      "metadata": 0
    },
    {
      "x": 12,
      "y": 63,
      "z": -4,
      "type": "stone_bricks",
      "metadata": 0
    },
    {
      "x": 12,
      "y": 63,
      "z": -3,
      "type": "stone_bricks",
      "metadata": 0
    },
    {
      "x": 12,
      "y": 63,
      "z": -2,
      "type": "stone_bricks",
      "metadata": 0
    },
    {
      "x": 12,
      "y": 63,
      "z": -1,
      "type": "stone_bricks",
      "metadata": 0
    },
    {
      "x": 12,
      "y": 63,
      "z": 0,
      "type": "stone_bricks",
      "metadata": 0
    },
    {
      "x": 12,
      "y": 63,
      "z": 1,
      "type": "stone_bricks",
      "metadata": 0
    },
    {
      "x": 12,
      "y": 63,
      "z": 2,
      "type": "stone_bricks",
      "metadata": 0
    },
    {
      "x": 12,
      "y": 63,
      "z": 3,
      "type": "stone_bricks",
      "metadata": 0
    },
    {
      "x": 12,
      "y": 63,
      "z": 4,
      "type": "stone_bricks",
      "metadata": 0
    },
    {
      "x": 13,
      "y": 63,
      "z": -5,
      "type": "stone_bricks",
      "metadata": 0
    },
    {
      "x": 13,
      "y": 63,
      "z": -4,
      "type": "stone_bricks",
      "metadata": 0
    },
    {
      "x": 13,
      "y": 63,
      "z": -3,
      "type": "stone_bricks",
      "metadata": 0
    },
    {
      "x": 13,
      "y": 63,
      "z": -2,
      "type": "stone_bricks",
      "metadata": 0
    },
    {
      "x": 13,
      "y": 63,
      "z": -1,
      "type": "stone_bricks",
      "metadata": 0
    },
    {
      "x": 13,
      "y": 63,
      "z": 0,
      "type": "stone_bricks",
      "metadata": 0
    },
    {
      "x": 13,
      "y": 63,
      "z": 1,
      "type": "stone_bricks",
      "metadata": 0
    },
    {
      "x": 13,
      "y": 63,
      "z": 2,
      "type": "stone_bricks",
      "metadata": 0
    },
    {
      "x": 13,
      "y": 63,
      "z": 3,
      "type": "stone_bricks",
      "metadata": 0
    },
    {
      "x": 13,
      "y": 63,
      "z": 4,
      "type": "stone_bricks",
      "metadata": 0
    },
    {
      "x": 14,
      "y": 63,
      "z": -5,
      "type": "stone_bricks",
      "metadata": 0
    },
    {
      "x": 14,
      "y": 63,
      "z": -4,
      "type": "stone_bricks",
      "metadata": 0
    },
    {
      "x": 14,
      "y": 63,
      "z": -3,
      "type": "stone_bricks",
      "metadata": 0
    },
    {
      "x": 14,
      "y": 63,
      "z": -2,
      "type": "stone_bricks",
      "metadata": 0
    },
    {
      "x": 14,
      "y": 63,
      "z": -1,
      "type": "stone_bricks",
      "metadata": 0
    },
    {
      "x": 14,
      "y": 63,
      "z": 0,
      "type": "stone_bricks",
      "metadata": 0
    },
    {
      "x": 14,
      "y": 63,
      "z": 1,
      "type": "stone_bricks",
      "metadata": 0
    },
    {
      "x": 14,
      "y": 63,
      "z": 2,
      "type": "stone_bricks",
      "metadata": 0
    },
    {
      "x": 14,
      "y": 63,
      "z": 3,
      "type": "stone_bricks",
      "metadata": 0
    },
    {
      "x": 14,
      "y": 63,
      "z": 4,
      "type": "stone_bricks",
      "metadata": 0
    },
    {
      "x": 15,
      "y": 63,
      "z": -5,
      "type": "stone_bricks",
      "metadata": 0
    },
    {
      "x": 15,
      "y": 63,
      "z": -4,
      "type": "stone_bricks",
      "metadata": 0
    },
    {
      "x": 15,
      "y": 63,
      "z": -3,
      "type": "stone_bricks",
      "metadata": 0
    },
    {
      "x": 15,
      "y": 63,
      "z": -2,
      "type": "stone_bricks",
      "metadata": 0
    },
    {
      "x": 15,
      "y": 63,
      "z": -1,
      "type": "stone_bricks",
      "metadata": 0
    },
    {
      "x": 15,
      "y": 63,
      "z": 0,
      "type": "stone_bricks",
      "metadata": 0
    },
    {
      "x": 15,
      "y": 63,
      "z": 1,
      "type": "stone_bricks",
      "metadata": 0
    },
    {
      "x": 15,
      "y": 63,
      "z": 2,
      "type": "stone_bricks",
      "metadata": 0
    },
    {
      "x": 15,
      "y": 63,
      "z": 3,
      "type": "stone_bricks",
      "metadata": 0
    },
    {
      "x": 15,
      "y": 63,
      "z": 4,
      "type": "stone_bricks",
      "metadata": 0
    },
    {
      "x": 16,
      "y": 63,
      "z": -5,
      "type": "stone_bricks",
      "metadata": 0
    },
    {
      "x": 16,
      "y": 63,
      "z": -4,
      "type": "stone_bricks",
      "metadata": 0
    },
    {
      "x": 16,
      "y": 63,
      "z": -3,
      "type": "stone_bricks",
      "metadata": 0
    },
    {
      "x": 16,
      "y": 63,
      "z": -2,
      "type": "stone_bricks",
      "metadata": 0
    },
    {
      "x": 16,
      "y": 63,
      "z": -1,
      "type": "stone_bricks",
      "metadata": 0
    },
    {
      "x": 16,
      "y": 63,
      "z": 0,
      "type": "stone_bricks",
      "metadata": 0
    },
    {
      "x": 16,
      "y": 63,
      "z": 1,
      "type": "stone_bricks",
      "metadata": 0
    },
    {
      "x": 16,
      "y": 63,
      "z": 2,
      "type": "stone_bricks",
      "metadata": 0
    },
    {
      "x": 16,
      "y": 63,
      "z": 3,
      "type": "stone_bricks",
      "metadata": 0
    },
    {
      "x": 16,
      "y": 63,
      "z": 4,
      "type": "stone_bricks",
      "metadata": 0
    },
    {
      "x": 17,
      "y": 63,
      "z": -5,
      "type": "stone_bricks",
      "metadata": 0
    },
    {
      "x": 17,
      "y": 63,
      "z": -4,
      "type": "stone_bricks",
      "metadata": 0
    },
    {
      "x": 17,
      "y": 63,
      "z": -3,
      "type": "stone_bricks",
      "metadata": 0
    },
    {
      "x": 17,
      "y": 63,
      "z": -2,
      "type": "stone_bricks",
      "metadata": 0
    },
    {
      "x": 17,
      "y": 63,
      "z": -1,
      "type": "stone_bricks",
      "metadata": 0
    },
    {
      "x": 17,
      "y": 63,
      "z": 0,
      "type": "stone_bricks",
      "metadata": 0
    },
    {
      "x": 17,
      "y": 63,
      "z": 1,
      "type": "stone_bricks",
      "metadata": 0
    },
    {
      "x": 17,
      "y": 63,
      "z": 2,
      "type": "stone_bricks",
      "metadata": 0
    },
    {
      "x": 17,
      "y": 63,
      "z": 3,
      "type": "stone_bricks",
      "metadata": 0
    },
    {
      "x": 17,
      "y": 63,
      "z": 4,
      "type": "stone_bricks",
      "metadata": 0
    },
    {
      "x": 18,
      "y": 63,
      "z": -5,
      "type": "stone_bricks",
      "metadata": 0
    },
    {
      "x": 18,
      "y": 63,
      "z": -4,
      "type": "stone_bricks",
      "metadata": 0
    },
    {
      "x": 18,
      "y": 63,
      "z": -3,
      "type": "stone_bricks",
      "metadata": 0
    },
    {
      "x": 18,
      "y": 63,
      "z": -2,
      "type": "stone_bricks",
      "metadata": 0
    },
    {
      "x": 18,
      "y": 63,
      "z": -1,
      "type": "stone_bricks",
      "metadata": 0
    },
    {
      "x": 18,
      "y": 63,
      "z": 0,
      "type": "stone_bricks",
      "metadata": 0
    },
    {
      "x": 18,
      "y": 63,
      "z": 1,
      "type": "stone_bricks",
      "metadata": 0
    },
    {
      "x": 18,
      "y": 63,
      "z": 2,
      "type": "stone_bricks",
      "metadata": 0
    },
    {
      "x": 18,
      "y": 63,
      "z": 3,
      "type": "stone_bricks",
      "metadata": 0
    },
    {
      "x": 18,
      "y": 63,
      "z": 4,
      "type": "stone_bricks",
      "metadata": 0
    },
    {
      "x": 19,
      "y": 63,
      "z": -5,
      "type": "stone_bricks",
      "metadata": 0
    },
    {
      "x": 19,
      "y": 63,
      "z": -4,
      "type": "stone_bricks",
      "metadata": 0
    },
    {
      "x": 19,
      "y": 63,
      "z": -3,
      "type": "stone_bricks",
      "metadata": 0
    },
    {
      "x": 19,
      "y": 63,
      "z": -2,
      "type": "stone_bricks",
      "metadata": 0
    },
    {
      "x": 19,
      "y": 63,
      "z": -1,
      "type": "stone_bricks",
      "metadata": 0
    },
    {
      "x": 19,
      "y": 63,
      "z": 0,
      "type": "stone_bricks",
      "metadata": 0
    },
    {
      "x": 19,
      "y": 63,
      "z": 1,
      "type": "stone_bricks",
      "metadata": 0
    },
    {
      "x": 19,
      "y": 63,
      "z": 2,
      "type": "stone_bricks",
      "metadata": 0
    },
    {
      "x": 19,
      "y": 63,
      "z": 3,
      "type": "stone_bricks",
      "metadata": 0
    },
    {
      "x": 19,
      "y": 63,
      "z": 4,
      "type": "stone_bricks",
      "metadata": 0
    },
    {
      "x": 20,
      "y": 63,
      "z": -5,
      "type": "stone_bricks",
      "metadata": 0
    },
    {
      "x": 20,
      "y": 63,
      "z": -4,
      "type": "stone_bricks",
      "metadata": 0
    },
    {
      "x": 20,
      "y": 63,
      "z": -3,
      "type": "stone_bricks",
      "metadata": 0
    },
    {
      "x": 20,
      "y": 63,
      "z": -2,
      "type": "stone_bricks",
      "metadata": 0
    },
    {
      "x": 20,
      "y": 63,
      "z": -1,
      "type": "stone_bricks",
      "metadata": 0
    },
    {
      "x": 20,
      "y": 63,
      "z": 0,
      "type": "stone_bricks",
      "metadata": 0
    },
    {
      "x": 20,
      "y": 63,
      "z": 1,
      "type": "stone_bricks",
      "metadata": 0
    },
    {
      "x": 20,
      "y": 63,
      "z": 2,
      "type": "stone_bricks",
      "metadata": 0
    },
    {
      "x": 20,
      "y": 63,
      "z": 3,
      "type": "stone_bricks",
      "metadata": 0
    },
    {
      "x": 20,
      "y": 63,
      "z": 4,
      "type": "stone_bricks",
      "metadata": 0
    },
    {
      "x": 21,
      "y": 63,
      "z": -5,
      "type": "stone_bricks",
      "metadata": 0
    },
    {
      "x": 21,
      "y": 63,
      "z": -4,
      "type": "stone_bricks",
      "metadata": 0
    },
    {
      "x": 21,
      "y": 63,
      "z": -3,
      "type": "stone_bricks",
      "metadata": 0
    },
    {
      "x": 21,
      "y": 63,
      "z": -2,
      "type": "stone_bricks",
      "metadata": 0
    },
    {
      "x": 21,
      "y": 63,
      "z": -1,
      "type": "stone_bricks",
      "metadata": 0
    },
    {
      "x": 21,
      "y": 63,
      "z": 0,
      "type": "stone_bricks",
      "metadata": 0
    },
    {
      "x": 21,
      "y": 63,
      "z": 1,
      "type": "stone_bricks",
      "metadata": 0
    },
    {
      "x": 21,
      "y": 63,
      "z": 2,
      "type": "stone_bricks",
      "metadata": 0
    },
    {
      "x": 21,
      "y": 63,
      "z": 3,
      "type": "stone_bricks",
      "metadata": 0
    },
    {
      "x": 21,
      "y": 63,
      "z": 4,
      "type": "stone_bricks",
      "metadata": 0
    },
    {
      "x": 22,
      "y": 63,
      "z": -5,
      "type": "stone_bricks",
      "metadata": 0
    },
    {
      "x": 22,
      "y": 63,
      "z": -4,
      "type": "stone_bricks",
      "metadata": 0
    },
    {
      "x": 22,
      "y": 63,
      "z": -3,
      "type": "stone_bricks",
      "metadata": 0
    },
    {
      "x": 22,
      "y": 63,
      "z": -2,
      "type": "stone_bricks",
      "metadata": 0
    },
    {
      "x": 22,
      "y": 63,
      "z": -1,
      "type": "stone_bricks",
      "metadata": 0
    },
    {
      "x": 22,
      "y": 63,
      "z": 0,
      "type": "stone_bricks",
      "metadata": 0
    },
    {
      "x": 22,
      "y": 63,
      "z": 1,
      "type": "stone_bricks",
      "metadata": 0
    },
    {
      "x": 22,
      "y": 63,
      "z": 2,
      "type": "stone_bricks",
      "metadata": 0
    },
    {
      "x": 22,
      "y": 63,
      "z": 3,
      "type": "stone_bricks",
      "metadata": 0
    },
    {
      "x": 22,
      "y": 63,
      "z": 4,
      "type": "stone_bricks",
      "metadata": 0
    },
    {
      "x": 23,
      "y": 63,
      "z": -5,
      "type": "stone_bricks",
      "metadata": 0
    },
    {
      "x": 23,
      "y": 63,
      "z": -4,
      "type": "stone_bricks",
      "metadata": 0
    },
    {
      "x": 23,
      "y": 63,
      "z": -3,
      "type": "stone_bricks",
      "metadata": 0
    },
    {
      "x": 23,
      "y": 63,
      "z": -2,
      "type": "stone_bricks",
      "metadata": 0
    },
    {
      "x": 23,
      "y": 63,
      "z": -1,
      "type": "stone_bricks",
      "metadata": 0
    },
    {
      "x": 23,
      "y": 63,
      "z": 0,
      "type": "stone_bricks",
      "metadata": 0
    },
    {
      "x": 23,
      "y": 63,
      "z": 1,
      "type": "stone_bricks",
      "metadata": 0
    },
    {
      "x": 23,
      "y": 63,
      "z": 2,
      "type": "stone_bricks",
      "metadata": 0
    },
    {
      "x": 23,
      "y": 63,
      "z": 3,
      "type": "stone_bricks",
      "metadata": 0
    },
    {
      "x": 23,
      "y": 63,
      "z": 4,
      "type": "stone_bricks",
      "metadata": 0
    },
    {
      "x": 24,
      "y": 63,
      "z": -5,
      "type": "stone_bricks",
      "metadata": 0
    },
    {
      "x": 24,
      "y": 63,
      "z": -4,
      "type": "stone_bricks",
      "metadata": 0
    },
    {
      "x": 24,
      "y": 63,
      "z": -3,
      "type": "stone_bricks",
      "metadata": 0
    },
    {
      "x": 24,
      "y": 63,
      "z": -2,
      "type": "stone_bricks",
      "metadata": 0
    },
    {
      "x": 24,
      "y": 63,
      "z": -1,
      "type": "stone_bricks",
      "metadata": 0
    },
    {
      "x": 24,
      "y": 63,
      "z": 0,
      "type": "stone_bricks",
      "metadata": 0
    },
    {
      "x": 24,
      "y": 63,
      "z": 1,
      "type": "stone_bricks",
      "metadata": 0
    },
    {
      "x": 24,
      "y": 63,
      "z": 2,
      "type": "stone_bricks",
      "metadata": 0
    },
    {
      "x": 24,
      "y": 63,
      "z": 3,
      "type": "stone_bricks",
      "metadata": 0
    },
    {
      "x": 24,
      "y": 63,
      "z": 4,
      "type": "stone_bricks",
      "metadata": 0
    },
    {
      "x": 25,
      "y": 63,
      "z": -5,
      "type": "stone_bricks",
      "metadata": 0
    },
    {
      "x": 25,
      "y": 63,
      "z": -4,
      "type": "stone_bricks",
      "metadata": 0
    },
    {
      "x": 25,
      "y": 63,
      "z": -3,
      "type": "stone_bricks",
      "metadata": 0
    },
    {
      "x": 25,
      "y": 63,
      "z": -2,
      "type": "stone_bricks",
      "metadata": 0
    },
    {
      "x": 25,
      "y": 63,
      "z": -1,
      "type": "stone_bricks",
      "metadata": 0
    },
    {
      "x": 25,
      "y": 63,
      "z": 0,
      "type": "stone_bricks",
      "metadata": 0
    },
    {
      "x": 25,
      "y": 63,
      "z": 1,
      "type": "stone_bricks",
      "metadata": 0
    },
    {
      "x": 25,
      "y": 63,
      "z": 2,
      "type": "stone_bricks",
      "metadata": 0
    },
    {
      "x": 25,
      "y": 63,
      "z": 3,
      "type": "stone_bricks",
      "metadata": 0
    },
    {
      "x": 25,
      "y": 63,
      "z": 4,
      "type": "stone_bricks",
      "metadata": 0
    },
    {
      "x": 26,
      "y": 63,
      "z": -5,
      "type": "stone_bricks",
      "metadata": 0
    },
    {
      "x": 26,
      "y": 63,
      "z": -4,
      "type": "stone_bricks",
      "metadata": 0
    },
    {
      "x": 26,
      "y": 63,
      "z": -3,
      "type": "stone_bricks",
      "metadata": 0
    },
    {
      "x": 26,
      "y": 63,
      "z": -2,
      "type": "stone_bricks",
      "metadata": 0
    },
    {
      "x": 26,
      "y": 63,
      "z": -1,
      "type": "stone_bricks",
      "metadata": 0
    },
    {
      "x": 26,
      "y": 63,
      "z": 0,
      "type": "stone_bricks",
      "metadata": 0
    },
    {
      "x": 26,
      "y": 63,
      "z": 1,
      "type": "stone_bricks",
      "metadata": 0
    },
    {
      "x": 26,
      "y": 63,
      "z": 2,
      "type": "stone_bricks",
      "metadata": 0
    },
    {
      "x": 26,
      "y": 63,
      "z": 3,
      "type": "stone_bricks",
      "metadata": 0
    },
    {
      "x": 26,
      "y": 63,
      "z": 4,
      "type": "stone_bricks",
      "metadata": 0
    },
    {
      "x": 27,
      "y": 63,
      "z": -5,
      "type": "stone_bricks",
      "metadata": 0
    },
    {
      "x": 27,
      "y": 63,
      "z": -4,
      "type": "stone_bricks",
      "metadata": 0
    },
    {
      "x": 27,
      "y": 63,
      "z": -3,
      "type": "stone_bricks",
      "metadata": 0
    },
    {
      "x": 27,
      "y": 63,
      "z": -2,
      "type": "stone_bricks",
      "metadata": 0
    },
    {
      "x": 27,
      "y": 63,
      "z": -1,
      "type": "stone_bricks",
      "metadata": 0
    },
    {
      "x": 27,
      "y": 63,
      "z": 0,
      "type": "stone_bricks",
      "metadata": 0
    },
    {
      "x": 27,
      "y": 63,
      "z": 1,
      "type": "stone_bricks",
      "metadata": 0
    },
    {
      "x": 27,
      "y": 63,
      "z": 2,
      "type": "stone_bricks",
      "metadata": 0
    },
    {
      "x": 27,
      "y": 63,
      "z": 3,
      "type": "stone_bricks",
      "metadata": 0
    },
    {
      "x": 27,
      "y": 63,
      "z": 4,
      "type": "stone_bricks",
      "metadata": 0
    },
    {
      "x": 28,
      "y": 63,
      "z": -5,
      "type": "stone_bricks",
      "metadata": 0
    },
    {
      "x": 28,
      "y": 63,
      "z": -4,
      "type": "stone_bricks",
      "metadata": 0
    },
    {
      "x": 28,
      "y": 63,
      "z": -3,
      "type": "stone_bricks",
      "metadata": 0
    },
    {
      "x": 28,
      "y": 63,
      "z": -2,
      "type": "stone_bricks",
      "metadata": 0
    },
    {
      "x": 28,
      "y": 63,
      "z": -1,
      "type": "stone_bricks",
      "metadata": 0
    },
    {
      "x": 28,
      "y": 63,
      "z": 0,
      "type": "stone_bricks",
      "metadata": 0
    },
    {
      "x": 28,
      "y": 63,
      "z": 1,
      "type": "stone_bricks",
      "metadata": 0
    },
    {
      "x": 28,
      "y": 63,
      "z": 2,
      "type": "stone_bricks",
      "metadata": 0
    },
    {
      "x": 28,
      "y": 63,
      "z": 3,
      "type": "stone_bricks",
      "metadata": 0
    },
    {
      "x": 28,
      "y": 63,
      "z": 4,
      "type": "stone_bricks",
      "metadata": 0
    },
    {
      "x": 29,
      "y": 63,
      "z": -5,
      "type": "stone_bricks",
      "metadata": 0
    },
    {
      "x": 29,
      "y": 63,
      "z": -4,
      "type": "stone_bricks",
      "metadata": 0
    },
    {
      "x": 29,
      "y": 63,
      "z": -3,
      "type": "stone_bricks",
      "metadata": 0
    },
    {
      "x": 29,
      "y": 63,
      "z": -2,
      "type": "stone_bricks",
      "metadata": 0
    },
    {
      "x": 29,
      "y": 63,
      "z": -1,
      "type": "stone_bricks",
      "metadata": 0
    },
    {
      "x": 29,
      "y": 63,
      "z": 0,
      "type": "stone_bricks",
      "metadata": 0
    },
    {
      "x": 29,
      "y": 63,
      "z": 1,
      "type": "stone_bricks",
      "metadata": 0
    },
    {
      "x": 29,
      "y": 63,
      "z": 2,
      "type": "stone_bricks",
      "metadata": 0
    },
    {
      "x": 29,
      "y": 63,
      "z": 3,
      "type": "stone_bricks",
      "metadata": 0
    },
    {
      "x": 29,
      "y": 63,
      "z": 4,
      "type": "stone_bricks",
      "metadata": 0
    },
    {
      "x": 30,
      "y": 63,
      "z": -5,
      "type": "stone_bricks",
      "metadata": 0
    },
    {
      "x": 30,
      "y": 63,
      "z": -4,
      "type": "stone_bricks",
      "metadata": 0
    },
    {
      "x": 30,
      "y": 63,
      "z": -3,
      "type": "stone_bricks",
      "metadata": 0
    },
    {
      "x": 30,
      "y": 63,
      "z": -2,
      "type": "stone_bricks",
      "metadata": 0
    },
    {
      "x": 30,
      "y": 63,
      "z": -1,
      "type": "stone_bricks",
      "metadata": 0
    },
    {
      "x": 30,
      "y": 63,
      "z": 0,
      "type": "stone_bricks",
      "metadata": 0
    },
    {
      "x": 30,
      "y": 63,
      "z": 1,
      "type": "stone_bricks",
      "metadata": 0
    },
    {
      "x": 30,
      "y": 63,
      "z": 2,
      "type": "stone_bricks",
      "metadata": 0
    },
    {
      "x": 30,
      "y": 63,
      "z": 3,
      "type": "stone_bricks",
      "metadata": 0
    },
    {
      "x": 30,
      "y": 63,
      "z": 4,
      "type": "stone_bricks",
      "metadata": 0
    },
    {
      "x": 31,
      "y": 63,
      "z": -5,
      "type": "stone_bricks",
      "metadata": 0
    },
    {
      "x": 31,
      "y": 63,
      "z": -4,
      "type": "stone_bricks",
      "metadata": 0
    },
    {
      "x": 31,
      "y": 63,
      "z": -3,
      "type": "stone_bricks",
      "metadata": 0
    },
    {
      "x": 31,
      "y": 63,
      "z": -2,
      "type": "stone_bricks",
      "metadata": 0
    },
    {
      "x": 31,
      "y": 63,
      "z": -1,
      "type": "stone_bricks",
      "metadata": 0
    },
    {
      "x": 31,
      "y": 63,
      "z": 0,
      "type": "stone_bricks",
      "metadata": 0
    },
    {
      "x": 31,
      "y": 63,
      "z": 1,
      "type": "stone_bricks",
      "metadata": 0
    },
    {
      "x": 31,
      "y": 63,
      "z": 2,
      "type": "stone_bricks",
      "metadata": 0
    },
    {
      "x": 31,
      "y": 63,
      "z": 3,
      "type": "stone_bricks",
      "metadata": 0
    },
    {
      "x": 31,
      "y": 63,
      "z": 4,
      "type": "stone_bricks",
      "metadata": 0
    },
    {
      "x": 32,
      "y": 63,
      "z": -5,
      "type": "stone_bricks",
      "metadata": 0
    },
    {
      "x": 32,
      "y": 63,
      "z": -4,
      "type": "stone_bricks",
      "metadata": 0
    },
    {
      "x": 32,
      "y": 63,
      "z": -3,
      "type": "stone_bricks",
      "metadata": 0
    },
    {
      "x": 32,
      "y": 63,
      "z": -2,
      "type": "stone_bricks",
      "metadata": 0
    },
    {
      "x": 32,
      "y": 63,
      "z": -1,
      "type": "stone_bricks",
      "metadata": 0
    },
    {
      "x": 32,
      "y": 63,
      "z": 0,
      "type": "stone_bricks",
      "metadata": 0
    },
    {
      "x": 32,
      "y": 63,
      "z": 1,
      "type": "stone_bricks",
      "metadata": 0
    },
    {
      "x": 32,
      "y": 63,
      "z": 2,
      "type": "stone_bricks",
      "metadata": 0
    },
    {
      "x": 32,
      "y": 63,
      "z": 3,
      "type": "stone_bricks",
      "metadata": 0
    },
    {
      "x": 32,
      "y": 63,
      "z": 4,
      "type": "stone_bricks",
      "metadata": 0
    },
    {
      "x": 33,
      "y": 63,
      "z": -5,
      "type": "stone_bricks",
      "metadata": 0
    },
    {
      "x": 33,
      "y": 63,
      "z": -4,
      "type": "stone_bricks",
      "metadata": 0
    },
    {
      "x": 33,
      "y": 63,
      "z": -3,
      "type": "stone_bricks",
      "metadata": 0
    },
    {
      "x": 33,
      "y": 63,
      "z": -2,
      "type": "stone_bricks",
      "metadata": 0
    },
    {
      "x": 33,
      "y": 63,
      "z": -1,
      "type": "stone_bricks",
      "metadata": 0
    },
    {
      "x": 33,
      "y": 63,
      "z": 0,
      "type": "stone_bricks",
      "metadata": 0
    },
    {
      "x": 33,
      "y": 63,
      "z": 1,
      "type": "stone_bricks",
      "metadata": 0
    },
    {
      "x": 33,
      "y": 63,
      "z": 2,
      "type": "stone_bricks",
      "metadata": 0
    },
    {
      "x": 33,
      "y": 63,
      "z": 3,
      "type": "stone_bricks",
      "metadata": 0
    },
    {
      "x": 33,
      "y": 63,
      "z": 4,
      "type": "stone_bricks",
      "metadata": 0
    },
    {
      "x": 34,
      "y": 63,
      "z": -5,
      "type": "stone_bricks",
      "metadata": 0
    },
    {
      "x": 34,
      "y": 63,
      "z": -4,
      "type": "stone_bricks",
      "metadata": 0
    },
    {
      "x": 34,
      "y": 63,
      "z": -3,
      "type": "stone_bricks",
      "metadata": 0
    },
    {
      "x": 34,
      "y": 63,
      "z": -2,
      "type": "stone_bricks",
      "metadata": 0
    },
    {
      "x": 34,
      "y": 63,
      "z": -1,
      "type": "stone_bricks",
      "metadata": 0
    },
    {
      "x": 34,
      "y": 63,
      "z": 0,
      "type": "stone_bricks",
      "metadata": 0
    },
    {
      "x": 34,
      "y": 63,
      "z": 1,
      "type": "stone_bricks",
      "metadata": 0
    },
    {
      "x": 34,
      "y": 63,
      "z": 2,
      "type": "stone_bricks",
      "metadata": 0
    },
    {
      "x": 34,
      "y": 63,
      "z": 3,
      "type": "stone_bricks",
      "metadata": 0
    },
    {
      "x": 34,
      "y": 63,
      "z": 4,
      "type": "stone_bricks",
      "metadata": 0
    },
    {
      "x": 35,
      "y": 63,
      "z": -5,
      "type": "stone_bricks",
      "metadata": 0
    },
    {
      "x": 35,
      "y": 63,
      "z": -4,
      "type": "stone_bricks",
      "metadata": 0
    },
    {
      "x": 35,
      "y": 63,
      "z": -3,
      "type": "stone_bricks",
      "metadata": 0
    },
    {
      "x": 35,
      "y": 63,
      "z": -2,
      "type": "stone_bricks",
      "metadata": 0
    },
    {
      "x": 35,
      "y": 63,
      "z": -1,
      "type": "stone_bricks",
      "metadata": 0
    },
    {
      "x": 35,
      "y": 63,
      "z": 0,
      "type": "stone_bricks",
      "metadata": 0
    },
    {
      "x": 35,
      "y": 63,
      "z": 1,
      "type": "stone_bricks",
      "metadata": 0
    },
    {
      "x": 35,
      "y": 63,
      "z": 2,
      "type": "stone_bricks",
      "metadata": 0
    },
    {
      "x": 35,
      "y": 63,
      "z": 3,
      "type": "stone_bricks",
      "metadata": 0
    },
    {
      "x": 35,
      "y": 63,
      "z": 4,
      "type": "stone_bricks",
      "metadata": 0
    },
    {
      "x": 36,
      "y": 63,
      "z": -5,
      "type": "stone_bricks",
      "metadata": 0
    },
    {
      "x": 36,
      "y": 63,
      "z": -4,
      "type": "stone_bricks",
      "metadata": 0
    },
    {
      "x": 36,
      "y": 63,
      "z": -3,
      "type": "stone_bricks",
      "metadata": 0
    },
    {
      "x": 36,
      "y": 63,
      "z": -2,
      "type": "stone_bricks",
      "metadata": 0
    },
    {
      "x": 36,
      "y": 63,
      "z": -1,
      "type": "stone_bricks",
      "metadata": 0
    },
    {
      "x": 36,
      "y": 63,
      "z": 0,
      "type": "stone_bricks",
      "metadata": 0
    },
    {
      "x": 36,
      "y": 63,
      "z": 1,
      "type": "stone_bricks",
      "metadata": 0
    },
    {
      "x": 36,
      "y": 63,
      "z": 2,
      "type": "stone_bricks",
      "metadata": 0
    },
    {
      "x": 36,
      "y": 63,
      "z": 3,
      "type": "stone_bricks",
      "metadata": 0
    },
    {
      "x": 36,
      "y": 63,
      "z": 4,
      "type": "stone_bricks",
      "metadata": 0
    },
    {
      "x": 37,
      "y": 63,
      "z": -5,
      "type": "stone_bricks",
      "metadata": 0
    },
    {
      "x": 37,
      "y": 63,
      "z": -4,
      "type": "stone_bricks",
      "metadata": 0
    },
    {
      "x": 37,
      "y": 63,
      "z": -3,
      "type": "stone_bricks",
      "metadata": 0
    },
    {
      "x": 37,
      "y": 63,
      "z": -2,
      "type": "stone_bricks",
      "metadata": 0
    },
    {
      "x": 37,
      "y": 63,
      "z": -1,
      "type": "stone_bricks",
      "metadata": 0
    },
    {
      "x": 37,
      "y": 63,
      "z": 0,
      "type": "stone_bricks",
      "metadata": 0
    },
    {
      "x": 37,
      "y": 63,
      "z": 1,
      "type": "stone_bricks",
      "metadata": 0
    },
    {
      "x": 37,
      "y": 63,
      "z": 2,
      "type": "stone_bricks",
      "metadata": 0
    },
    {
      "x": 37,
      "y": 63,
      "z": 3,
      "type": "stone_bricks",
      "metadata": 0
    },
    {
      "x": 37,
      "y": 63,
      "z": 4,
      "type": "stone_bricks",
      "metadata": 0
    },
    {
      "x": 38,
      "y": 63,
      "z": -5,
      "type": "stone_bricks",
      "metadata": 0
    },
    {
      "x": 38,
      "y": 63,
      "z": -4,
      "type": "stone_bricks",
      "metadata": 0
    },
    {
      "x": 38,
      "y": 63,
      "z": -3,
      "type": "stone_bricks",
      "metadata": 0
    },
    {
      "x": 38,
      "y": 63,
      "z": -2,
      "type": "stone_bricks",
      "metadata": 0
    },
    {
      "x": 38,
      "y": 63,
      "z": -1,
      "type": "stone_bricks",
      "metadata": 0
    },
    {
      "x": 38,
      "y": 63,
      "z": 0,
      "type": "stone_bricks",
      "metadata": 0
    },
    {
      "x": 38,
      "y": 63,
      "z": 1,
      "type": "stone_bricks",
      "metadata": 0
    },
    {
      "x": 38,
      "y": 63,
      "z": 2,
      "type": "stone_bricks",
      "metadata": 0
    },
    {
      "x": 38,
      "y": 63,
      "z": 3,
      "type": "stone_bricks",
      "metadata": 0
    },
    {
      "x": 38,
      "y": 63,
      "z": 4,
      "type": "stone_bricks",
      "metadata": 0
    },
    {
      "x": 39,
      "y": 63,
      "z": -5,
      "type": "stone_bricks",
      "metadata": 0
    },
    {
      "x": 39,
      "y": 63,
      "z": -4,
      "type": "stone_bricks",
      "metadata": 0
    },
    {
      "x": 39,
      "y": 63,
      "z": -3,
      "type": "stone_bricks",
      "metadata": 0
    },
    {
      "x": 39,
      "y": 63,
      "z": -2,
      "type": "stone_bricks",
      "metadata": 0
    },
    {
      "x": 39,
      "y": 63,
      "z": -1,
      "type": "stone_bricks",
      "metadata": 0
    },
    {
      "x": 39,
      "y": 63,
      "z": 0,
      "type": "stone_bricks",
      "metadata": 0
    },
    {
      "x": 39,
      "y": 63,
      "z": 1,
      "type": "stone_bricks",
      "metadata": 0
    },
    {
      "x": 39,
      "y": 63,
      "z": 2,
      "type": "stone_bricks",
      "metadata": 0
    },
    {
      "x": 39,
      "y": 63,
      "z": 3,
      "type": "stone_bricks",
      "metadata": 0
    },
    {
      "x": 39,
      "y": 63,
      "z": 4,
      "type": "stone_bricks",
      "metadata": 0
    },
    {
      "x": 40,
      "y": 63,
      "z": -5,
      "type": "stone_bricks",
      "metadata": 0
    },
    {
      "x": 40,
      "y": 63,
      "z": -4,
      "type": "stone_bricks",
      "metadata": 0
    },
    {
      "x": 40,
      "y": 63,
      "z": -3,
      "type": "stone_bricks",
      "metadata": 0
    },
    {
      "x": 40,
      "y": 63,
      "z": -2,
      "type": "stone_bricks",
      "metadata": 0
    },
    {
      "x": 40,
      "y": 63,
      "z": -1,
      "type": "stone_bricks",
      "metadata": 0
    },
    {
      "x": 40,
      "y": 63,
      "z": 0,
      "type": "stone_bricks",
      "metadata": 0
    },
    {
      "x": 40,
      "y": 63,
      "z": 1,
      "type": "stone_bricks",
      "metadata": 0
    },
    {
      "x": 40,
      "y": 63,
      "z": 2,
      "type": "stone_bricks",
      "metadata": 0
    },
    {
      "x": 40,
      "y": 63,
      "z": 3,
      "type": "stone_bricks",
      "metadata": 0
    },
    {
      "x": 40,
      "y": 63,
      "z": 4,
      "type": "stone_bricks",
      "metadata": 0
    },
    {
      "x": 41,
      "y": 63,
      "z": -5,
      "type": "stone_bricks",
      "metadata": 0
    },
    {
      "x": 41,
      "y": 63,
      "z": -4,
      "type": "stone_bricks",
      "metadata": 0
    },
    {
      "x": 41,
      "y": 63,
      "z": -3,
      "type": "stone_bricks",
      "metadata": 0
    },
    {
      "x": 41,
      "y": 63,
      "z": -2,
      "type": "stone_bricks",
      "metadata": 0
    },
    {
      "x": 41,
      "y": 63,
      "z": -1,
      "type": "stone_bricks",
      "metadata": 0
    },
    {
      "x": 41,
      "y": 63,
      "z": 0,
      "type": "stone_bricks",
      "metadata": 0
    },
    {
      "x": 41,
      "y": 63,
      "z": 1,
      "type": "stone_bricks",
      "metadata": 0
    },
    {
      "x": 41,
      "y": 63,
      "z": 2,
      "type": "stone_bricks",
      "metadata": 0
    },
    {
      "x": 41,
      "y": 63,
      "z": 3,
      "type": "stone_bricks",
      "metadata": 0
    },
    {
      "x": 41,
      "y": 63,
      "z": 4,
      "type": "stone_bricks",
      "metadata": 0
    },
    {
      "x": 42,
      "y": 63,
      "z": -5,
      "type": "stone_bricks",
      "metadata": 0
    },
    {
      "x": 42,
      "y": 63,
      "z": -4,
      "type": "stone_bricks",
      "metadata": 0
    },
    {
      "x": 42,
      "y": 63,
      "z": -3,
      "type": "stone_bricks",
      "metadata": 0
    },
    {
      "x": 42,
      "y": 63,
      "z": -2,
      "type": "stone_bricks",
      "metadata": 0
    },
    {
      "x": 42,
      "y": 63,
      "z": -1,
      "type": "stone_bricks",
      "metadata": 0
    },
    {
      "x": 42,
      "y": 63,
      "z": 0,
      "type": "stone_bricks",
      "metadata": 0
    },
    {
      "x": 42,
      "y": 63,
      "z": 1,
      "type": "stone_bricks",
      "metadata": 0
    },
    {
      "x": 42,
      "y": 63,
      "z": 2,
      "type": "stone_bricks",
      "metadata": 0
    },
    {
      "x": 42,
      "y": 63,
      "z": 3,
      "type": "stone_bricks",
      "metadata": 0
    },
    {
      "x": 42,
      "y": 63,
      "z": 4,
      "type": "stone_bricks",
      "metadata": 0
    },
    {
      "x": 43,
      "y": 63,
      "z": -5,
      "type": "stone_bricks",
      "metadata": 0
    },
    {
      "x": 43,
      "y": 63,
      "z": -4,
      "type": "stone_bricks",
      "metadata": 0
    },
    {
      "x": 43,
      "y": 63,
      "z": -3,
      "type": "stone_bricks",
      "metadata": 0
    },
    {
      "x": 43,
      "y": 63,
      "z": -2,
      "type": "stone_bricks",
      "metadata": 0
    },
    {
      "x": 43,
      "y": 63,
      "z": -1,
      "type": "stone_bricks",
      "metadata": 0
    },
    {
      "x": 43,
      "y": 63,
      "z": 0,
      "type": "stone_bricks",
      "metadata": 0
    },
    {
      "x": 43,
      "y": 63,
      "z": 1,
      "type": "stone_bricks",
      "metadata": 0
    },
    {
      "x": 43,
      "y": 63,
      "z": 2,
      "type": "stone_bricks",
      "metadata": 0
    },
    {
      "x": 43,
      "y": 63,
      "z": 3,
      "type": "stone_bricks",
      "metadata": 0
    },
    {
      "x": 43,
      "y": 63,
      "z": 4,
      "type": "stone_bricks",
      "metadata": 0
    },
    {
      "x": 44,
      "y": 63,
      "z": -5,
      "type": "stone_bricks",
      "metadata": 0
    },
    {
      "x": 44,
      "y": 63,
      "z": -4,
      "type": "stone_bricks",
      "metadata": 0
    },
    {
      "x": 44,
      "y": 63,
      "z": -3,
      "type": "stone_bricks",
      "metadata": 0
    },
    {
      "x": 44,
      "y": 63,
      "z": -2,
      "type": "stone_bricks",
      "metadata": 0
    },
    {
      "x": 44,
      "y": 63,
      "z": -1,
      "type": "stone_bricks",
      "metadata": 0
    },
    {
      "x": 44,
      "y": 63,
      "z": 0,
      "type": "stone_bricks",
      "metadata": 0
    },
    {
      "x": 44,
      "y": 63,
      "z": 1,
      "type": "stone_bricks",
      "metadata": 0
    },
    {
      "x": 44,
      "y": 63,
      "z": 2,
      "type": "stone_bricks",
      "metadata": 0
    },
    {
      "x": 44,
      "y": 63,
      "z": 3,
      "type": "stone_bricks",
      "metadata": 0
    },
    {
      "x": 44,
      "y": 63,
      "z": 4,
      "type": "stone_bricks",
      "metadata": 0
    },
    {
      "x": 45,
      "y": 63,
      "z": -5,
      "type": "stone_bricks",
      "metadata": 0
    },
    {
      "x": 45,
      "y": 63,
      "z": -4,
      "type": "stone_bricks",
      "metadata": 0
    },
    {
      "x": 45,
      "y": 63,
      "z": -3,
      "type": "stone_bricks",
      "metadata": 0
    },
    {
      "x": 45,
      "y": 63,
      "z": -2,
      "type": "stone_bricks",
      "metadata": 0
    },
    {
      "x": 45,
      "y": 63,
      "z": -1,
      "type": "stone_bricks",
      "metadata": 0
    },
    {
      "x": 45,
      "y": 63,
      "z": 0,
      "type": "stone_bricks",
      "metadata": 0
    },
    {
      "x": 45,
      "y": 63,
      "z": 1,
      "type": "stone_bricks",
      "metadata": 0
    },
    {
      "x": 45,
      "y": 63,
      "z": 2,
      "type": "stone_bricks",
      "metadata": 0
    },
    {
      "x": 45,
      "y": 63,
      "z": 3,
      "type": "stone_bricks",
      "metadata": 0
    },
    {
      "x": 45,
      "y": 63,
      "z": 4,
      "type": "stone_bricks",
      "metadata": 0
    },
    {
      "x": 46,
      "y": 63,
      "z": -5,
      "type": "stone_bricks",
      "metadata": 0
    },
    {
      "x": 46,
      "y": 63,
      "z": -4,
      "type": "stone_bricks",
      "metadata": 0
    },
    {
      "x": 46,
      "y": 63,
      "z": -3,
      "type": "stone_bricks",
      "metadata": 0
    },
    {
      "x": 46,
      "y": 63,
      "z": -2,
      "type": "stone_bricks",
      "metadata": 0
    },
    {
      "x": 46,
      "y": 63,
      "z": -1,
      "type": "stone_bricks",
      "metadata": 0
    },
    {
      "x": 46,
      "y": 63,
      "z": 0,
      "type": "stone_bricks",
      "metadata": 0
    },
    {
      "x": 46,
      "y": 63,
      "z": 1,
      "type": "stone_bricks",
      "metadata": 0
    },
    {
      "x": 46,
      "y": 63,
      "z": 2,
      "type": "stone_bricks",
      "metadata": 0
    },
    {
      "x": 46,
      "y": 63,
      "z": 3,
      "type": "stone_bricks",
      "metadata": 0
    },
    {
      "x": 46,
      "y": 63,
      "z": 4,
      "type": "stone_bricks",
      "metadata": 0
    },
    {
      "x": 47,
      "y": 63,
      "z": -5,
      "type": "stone_bricks",
      "metadata": 0
    },
    {
      "x": 47,
      "y": 63,
      "z": -4,
      "type": "stone_bricks",
      "metadata": 0
    },
    {
      "x": 47,
      "y": 63,
      "z": -3,
      "type": "stone_bricks",
      "metadata": 0
    },
    {
      "x": 47,
      "y": 63,
      "z": -2,
      "type": "stone_bricks",
      "metadata": 0
    },
    {
      "x": 47,
      "y": 63,
      "z": -1,
      "type": "stone_bricks",
      "metadata": 0
    },
    {
      "x": 47,
      "y": 63,
      "z": 0,
      "type": "stone_bricks",
      "metadata": 0
    },
    {
      "x": 47,
      "y": 63,
      "z": 1,
      "type": "stone_bricks",
      "metadata": 0
    },
    {
      "x": 47,
      "y": 63,
      "z": 2,
      "type": "stone_bricks",
      "metadata": 0
    },
    {
      "x": 47,
      "y": 63,
      "z": 3,
      "type": "stone_bricks",
      "metadata": 0
    },
    {
      "x": 47,
      "y": 63,
      "z": 4,
      "type": "stone_bricks",
      "metadata": 0
    },
    {
      "x": 48,
      "y": 63,
      "z": -5,
      "type": "stone_bricks",
      "metadata": 0
    },
    {
      "x": 48,
      "y": 63,
      "z": -4,
      "type": "stone_bricks",
      "metadata": 0
    },
    {
      "x": 48,
      "y": 63,
      "z": -3,
      "type": "stone_bricks",
      "metadata": 0
    },
    {
      "x": 48,
      "y": 63,
      "z": -2,
      "type": "stone_bricks",
      "metadata": 0
    },
    {
      "x": 48,
      "y": 63,
      "z": -1,
      "type": "stone_bricks",
      "metadata": 0
    },
    {
      "x": 48,
      "y": 63,
      "z": 0,
      "type": "stone_bricks",
      "metadata": 0
    },
    {
      "x": 48,
      "y": 63,
      "z": 1,
